<mujoco model="laboratory_complex">
  <compiler angle="degree" coordinate="local" inertiafromgeom="true" />

  <option timestep="0.005" integrator="RK4">
    <flag warmstart="enable" />
  </option>
  
  <visual>
    <headlight ambient="0.5 0.5 0.5" diffuse="0.8 0.8 0.8" specular="0.3 0.3 0.3" />
    <rgba haze="0.15 0.25 0.35 1" />
    <quality shadowsize="2048" />
    <map stiffness="700" shadowscale="0.5" fogstart="10" fogend="15" />
  </visual>

  <default>
<default class="ur10e_ur10e">
      <material specular="0.5" shininess="0.25" />
      <joint axis="0 1 0" range="-360.00027 360.00027" armature="0.1" />
      <position ctrlrange="-359.99511 359.99511" />
      <general biastype="affine" ctrlrange="-359.99511 359.99511" gainprm="5000" biasprm="0 -5000 -500" />
      <default class="ur10e_size4">
        <joint damping="10" />
        <general forcerange="-330 330" />
      </default>
      <default class="ur10e_size3">
        <joint damping="5" />
        <general forcerange="-150 150" />
        <default class="ur10e_size3_limited">
          <joint range="-179.99469 179.99469" />
          <general ctrlrange="-179.99469 179.99469" />
        </default>
      </default>
      <default class="ur10e_size2">
        <joint damping="2" />
        <general forcerange="-56 56" />
      </default>
      <default class="ur10e_visual">
        <geom type="mesh" contype="0" conaffinity="0" group="2" />
      </default>
      <default class="ur10e_collision">
        <geom type="capsule" group="3" />
        <default class="ur10e_eef_collision">
          <geom type="cylinder" />
        </default>
      </default>
      <site size="0.001" rgba="0.5 0.5 0.5 0.3" group="4" />
    </default>
  <default class="gripper_2f85">
      <mesh scale="0.001 0.001 0.001" />
      <general biastype="affine" />

      <joint axis="1 0 0" />
      <default class="gripper_driver">
        <joint range="0.00000 45.83662" armature="0.005" damping="0.1" solimplimit="0.95 0.99 0.001" solreflimit="0.005 1" />
      </default>
      <default class="gripper_follower">
        <joint range="-49.99996 49.99996" armature="0.001" pos="0 -0.018 0.0065" solimplimit="0.95 0.99 0.001" solreflimit="0.005 1" />
      </default>
      <default class="gripper_spring_link">
        <joint range="-17.00000 45.83662" armature="0.001" stiffness="0.05" springref="2.62" damping="0.00125" />
      </default>
      <default class="gripper_coupler">
        <joint range="-89.95437 0.00000" armature="0.001" solimplimit="0.95 0.99 0.001" solreflimit="0.005 1" />
      </default>

      <default class="gripper_visual">
        <geom type="mesh" contype="0" conaffinity="0" group="2" />
      </default>
      <default class="gripper_collision">
        <geom type="mesh" group="3" />
        <default class="gripper_pad_box1">
          <geom mass="0" type="box" pos="0 -0.0026 0.028125" size="0.011 0.004 0.009375" friction="0.7" solimp="0.95 0.99 0.001" solref="0.004 1" priority="1" rgba="0.55 0.55 0.55 1" />
        </default>
        <default class="gripper_pad_box2">
          <geom mass="0" type="box" pos="0 -0.0026 0.009375" size="0.011 0.004 0.009375" friction="0.6" solimp="0.95 0.99 0.001" solref="0.004 1" priority="1" rgba="0.45 0.45 0.45 1" />
        </default>
      </default>
    </default>
    <default class="tidybot_base">
      <default class="tidybot_visual">
        <geom type="mesh" contype="0" conaffinity="0" group="2"/>
      </default>
      <default class="tidybot_collision">
        <geom type="mesh" group="3"/>
      </default>
    </default>
  </default>
<asset>
    <material name="tidybot_black" rgba="0.11372549 0.11372549 0.10196078 1"/>
    <material name="tidybot_gray" rgba="0.62745098 0.65098039 0.64705882 1"/>
    <material name="tidybot_dark_gray" rgba="0.35294118 0.37647059 0.37254902 1"/>
    <mesh file="assets/stanford_tidybot/assets/base/bumper.stl" name="tidybot_bumper"/>
    <mesh file="assets/stanford_tidybot/assets/base/bottom_plate.stl" name="tidybot_bottom_plate"/>
    <mesh file="assets/stanford_tidybot/assets/base/body.stl" name="tidybot_body"/>
    <mesh file="assets/stanford_tidybot/assets/base/top_plate.stl" name="tidybot_top_plate"/>
    <mesh file="assets/stanford_tidybot/assets/base/arm_plate.stl" name="tidybot_arm_plate"/>

    <texture name="floor_tile" type="2d" builtin="checker" rgb1="0.8 0.8 0.8" rgb2="0.7 0.7 0.7" width="512" height="512" />
    <material name="floor_mat" texture="floor_tile" reflectance="0.1" />
    <material name="chem_floor_epoxy" rgba="0.8 0.85 0.9 1" reflectance="0.15" />
    <material name="wall_mat" rgba="0.9 0.9 0.85 1" reflectance="0.05" />
    <material name="chem_wall_tile" rgba="0.9 0.95 0.98 1" reflectance="0.1" />
    <material name="corridor_mat" rgba="0.85 0.85 0.85 1" />
    <material name="door_mat" rgba="0.6 0.4 0.3 1" />
    <material name="physics_accent" rgba="0.6 0.7 0.9 1" />
    <material name="chemistry_accent" rgba="0.9 0.7 0.6 1" />
    <material name="biology_accent" rgba="0.7 0.9 0.7 1" />
    <material name="fume_hood_mat" rgba="0.5 0.5 0.5 1" />
    <material name="granite_mat" rgba="0.3 0.3 0.3 1" reflectance="0.15" />
    <material name="sink_mat" rgba="0.4 0.5 0.6 1" />
    <material name="organic_zone_mat" rgba="0.85 0.7 0.6 1" />
    <material name="inorganic_zone_mat" rgba="0.6 0.75 0.85 1" />
    <material name="fume_hood_frame" rgba="0.35 0.35 0.35 1" />
    <material name="fume_hood_glass" rgba="0.6 0.7 0.9 0.3" reflectance="0.3" />
    <material name="corrosion_shelf" rgba="0.4 0.4 0.45 1" />
    <material name="hvac_unit_mat" rgba="0.6 0.6 0.65 1" />
    <material name="hvac_vent_mat" rgba="0.85 0.9 0.95 1" />
  

<material class="ur10e_ur10e" name="ur10e_black" rgba="0.033 0.033 0.033 1" />
    <material class="ur10e_ur10e" name="ur10e_jointgray" rgba="0.278 0.278 0.278 1" />
    <material class="ur10e_ur10e" name="ur10e_linkgray" rgba="0.82 0.82 0.82 1" />
    <material class="ur10e_ur10e" name="ur10e_urblue" rgba="0.49 0.678 0.8 1" />

    <mesh file="assets/ur10e/base_0.obj" name="ur10e_base_0" />
    <mesh file="assets/ur10e/base_1.obj" name="ur10e_base_1" />
    <mesh file="assets/ur10e/shoulder_0.obj" name="ur10e_shoulder_0" />
    <mesh file="assets/ur10e/shoulder_1.obj" name="ur10e_shoulder_1" />
    <mesh file="assets/ur10e/shoulder_2.obj" name="ur10e_shoulder_2" />
    <mesh file="assets/ur10e/upperarm_0.obj" name="ur10e_upperarm_0" />
    <mesh file="assets/ur10e/upperarm_1.obj" name="ur10e_upperarm_1" />
    <mesh file="assets/ur10e/upperarm_2.obj" name="ur10e_upperarm_2" />
    <mesh file="assets/ur10e/upperarm_3.obj" name="ur10e_upperarm_3" />
    <mesh file="assets/ur10e/forearm_0.obj" name="ur10e_forearm_0" />
    <mesh file="assets/ur10e/forearm_1.obj" name="ur10e_forearm_1" />
    <mesh file="assets/ur10e/forearm_2.obj" name="ur10e_forearm_2" />
    <mesh file="assets/ur10e/forearm_3.obj" name="ur10e_forearm_3" />
    <mesh file="assets/ur10e/wrist1_0.obj" name="ur10e_wrist1_0" />
    <mesh file="assets/ur10e/wrist1_1.obj" name="ur10e_wrist1_1" />
    <mesh file="assets/ur10e/wrist1_2.obj" name="ur10e_wrist1_2" />
    <mesh file="assets/ur10e/wrist2_0.obj" name="ur10e_wrist2_0" />
    <mesh file="assets/ur10e/wrist2_1.obj" name="ur10e_wrist2_1" />
    <mesh file="assets/ur10e/wrist2_2.obj" name="ur10e_wrist2_2" />
    <mesh file="assets/ur10e/wrist3.obj" name="ur10e_wrist3" />
  <material name="gripper_metal" rgba="0.58 0.58 0.58 1" />
    <material name="gripper_silicone" rgba="0.1882 0.1882 0.1882 1" />
    <material name="gripper_gray" rgba="0.4627 0.4627 0.4627 1" />
    <material name="gripper_black" rgba="0.149 0.149 0.149 1" />

    <mesh class="gripper_2f85" file="assets/robotiq_2f85/base_mount.stl" name="gripper_base_mount" />
    <mesh class="gripper_2f85" file="assets/robotiq_2f85/base.stl" name="gripper_base" />
    <mesh class="gripper_2f85" file="assets/robotiq_2f85/driver.stl" name="gripper_driver" />
    <mesh class="gripper_2f85" file="assets/robotiq_2f85/coupler.stl" name="gripper_coupler" />
    <mesh class="gripper_2f85" file="assets/robotiq_2f85/follower.stl" name="gripper_follower" />
    <mesh class="gripper_2f85" file="assets/robotiq_2f85/pad.stl" name="gripper_pad" />
    <mesh class="gripper_2f85" file="assets/robotiq_2f85/silicone_pad.stl" name="gripper_silicone_pad" />
    <mesh class="gripper_2f85" file="assets/robotiq_2f85/spring_link.stl" name="gripper_spring_link" />
  
  </asset>

  <worldbody>

  
    <light directional="true" pos="0 0 10" dir="0 0 -1" diffuse="0.8 0.8 0.8" specular="0.2 0.2 0.2" />
    <light directional="true" pos="5 10 8" dir="-1 -1 -1" diffuse="0.5 0.5 0.5" />

    
    

    
    <geom name="corridor_floor" type="box" pos="0 9 0" size="1.25 9 0.1" material="corridor_mat" contype="1" conaffinity="1" />

    
    <geom name="corridor_wall_south" type="box" pos="0 0 1.6" size="1.25 0.1 1.6" material="wall_mat" contype="1" conaffinity="1" />
    <geom name="corridor_wall_north" type="box" pos="0 18 1.6" size="1.25 0.1 1.6" material="wall_mat" contype="1" conaffinity="1" />

    
    

    
    <geom name="physics_floor" type="box" pos="-4.25 9 0" size="3 4 0.1" material="floor_mat" rgba="0.6 0.7 0.9 0.3" contype="1" conaffinity="1" />

    
    <geom name="physics_wall_north" type="box" pos="-4.25 13 1.6" size="3 0.1 1.6" material="wall_mat" contype="1" conaffinity="1" />
    <geom name="physics_wall_south" type="box" pos="-4.25 5 1.6" size="3 0.1 1.6" material="wall_mat" contype="1" conaffinity="1" />
    <geom name="physics_wall_west" type="box" pos="-7.25 9 1.6" size="0.1 4 1.6" material="wall_mat" contype="1" conaffinity="1" />

    
    <geom name="physics_wall_east_1" type="box" pos="-1.25 4.15 1.6" size="0.1 4.25 1.6" material="wall_mat" contype="1" conaffinity="1" />
    <geom name="physics_wall_east_2" type="box" pos="-1.25 13.85 1.6" size="0.1 4.25 1.6" material="wall_mat" contype="1" conaffinity="1" />

    
    <geom name="physics_marker" type="box" pos="-4.25 9 0.075" size="0.5 0.3 0.05" rgba="0.6 0.7 0.9 1" contype="0" conaffinity="0" />

    

    
    <body name="physics_main_table_body" pos="-4.25 9 0.4">
        
        <geom name="physics_main_table_top" type="box" pos="0 0 0.415" size="0.61 1.51 0.025" rgba="0.3 0.3 0.3 1" contype="1" conaffinity="1" />
        
        <geom name="phys_table_leg_1" type="cylinder" pos="0.5 1.4 -0.005" size="0.05 0.395" rgba="0.4 0.4 0.4 1" />
        <geom name="phys_table_leg_2" type="cylinder" pos="0.5 -1.4 -0.005" size="0.05 0.395" rgba="0.4 0.4 0.4 1" />
        <geom name="phys_table_leg_3" type="cylinder" pos="-0.5 1.4 -0.005" size="0.05 0.395" rgba="0.4 0.4 0.4 1" />
        <geom name="phys_table_leg_4" type="cylinder" pos="-0.5 -1.4 -0.005" size="0.05 0.395" rgba="0.4 0.4 0.4 1" />
    </body>

    
    
    <body name="oscilloscope_body" pos="-4.25 7.8 0.94">
        <freejoint />
        
        <geom name="oscilloscope_case" type="box" pos="0 0 0" size="0.15 0.2 0.1" rgba="0.7 0.7 0.7 1" contype="1" conaffinity="1" />
        
        <geom name="oscilloscope_screen" type="box" pos="-0.04 -0.2 0.02" size="0.06 0.005 0.05" rgba="0.1 0.4 0.2 1" contype="0" conaffinity="0" />
        
        <geom name="osc_knob_1" type="cylinder" pos="0.08 -0.2 0.05" size="0.015 0.01" euler="90 0 0" rgba="0.1 0.1 0.1 1" />
        <geom name="osc_knob_2" type="cylinder" pos="0.08 -0.2 0.0" size="0.015 0.01" euler="90 0 0" rgba="0.1 0.1 0.1 1" />
        <geom name="osc_knob_3" type="cylinder" pos="0.08 -0.2 -0.05" size="0.015 0.01" euler="90 0 0" rgba="0.1 0.1 0.1 1" />
        
        <geom name="osc_handle_top" type="box" pos="0 0 0.1" size="0.1 0.02 0.01" rgba="0.2 0.2 0.2 1" />
        <geom name="osc_handle_left" type="box" pos="-0.1 0 0.08" size="0.01 0.02 0.03" rgba="0.2 0.2 0.2 1" />
        <geom name="osc_handle_right" type="box" pos="0.1 0 0.08" size="0.01 0.02 0.03" rgba="0.2 0.2 0.2 1" />
    </body>

    
    <body name="mechanics_platform_body" pos="-4.5 9 0.92">
        <freejoint />
        
        <geom name="mechanics_base" type="box" pos="0 0 -0.04" size="0.25 0.25 0.04" rgba="0.4 0.4 0.4 1" contype="1" conaffinity="1" />
        
        <geom name="mechanics_top" type="box" pos="0 0 0.04" size="0.2 0.2 0.02" rgba="0.6 0.6 0.6 1" />
        
        <geom name="mech_post_1" type="cylinder" pos="0.15 0.15 0" size="0.02 0.04" rgba="0.3 0.3 0.3 1" />
        <geom name="mech_post_2" type="cylinder" pos="0.15 -0.15 0" size="0.02 0.04" rgba="0.3 0.3 0.3 1" />
        <geom name="mech_post_3" type="cylinder" pos="-0.15 0.15 0" size="0.02 0.04" rgba="0.3 0.3 0.3 1" />
        <geom name="mech_post_4" type="cylinder" pos="-0.15 -0.15 0" size="0.02 0.04" rgba="0.3 0.3 0.3 1" />
    </body>

    
    <body name="power_supply_body" pos="-3.9 9 0.92">
        <freejoint />
        
        <geom name="power_supply_case" type="box" pos="0 0 0" size="0.12 0.15 0.08" rgba="0.85 0.85 0.8 1" contype="1" conaffinity="1" />
        
        <geom name="power_display" type="box" pos="0 -0.15 0.03" size="0.06 0.005 0.02" rgba="0.8 0.2 0.2 1" contype="0" conaffinity="0" />
        
        <geom name="ps_term_red" type="cylinder" pos="-0.05 -0.15 -0.04" size="0.01 0.015" euler="90 0 0" rgba="0.9 0.1 0.1 1" />
        <geom name="ps_term_black" type="cylinder" pos="0.05 -0.15 -0.04" size="0.01 0.015" euler="90 0 0" rgba="0.1 0.1 0.1 1" />
        <geom name="ps_knob" type="cylinder" pos="0 -0.15 -0.04" size="0.02 0.01" euler="90 0 0" rgba="0.2 0.2 0.2 1" />
    </body>

    
    <body name="laser_source_body" pos="-4.25 10.2 0.88">
        <freejoint />
        
        <geom name="laser_mount" type="box" pos="0 0 0" size="0.08 0.08 0.04" rgba="0.2 0.2 0.2 1" contype="1" conaffinity="1" />
        
        <geom name="laser_tube" type="cylinder" pos="0 0 0.09" size="0.04 0.15" euler="90 0 0" rgba="0.7 0.2 0.2 1" contype="1" conaffinity="1" />
        
        <geom name="laser_aperture" type="cylinder" pos="0 -0.15 0.09" size="0.005 0.01" euler="90 0 0" rgba="0 0 0 1" />
    </body>

    
    <body name="sensor_1_body" pos="-4.6 8.2 0.90">
        <freejoint />
        <geom name="sensor_1_case" type="box" pos="0 0 0" size="0.03 0.03 0.06" rgba="0.2 0.4 0.6 1" contype="1" conaffinity="1" />
        <geom name="sensor_1_probe" type="cylinder" pos="0 0 -0.06" size="0.005 0.04" rgba="0.8 0.8 0.8 1" />
    </body>
    <body name="sensor_2_body" pos="-3.9 8.2 0.90">
        <freejoint />
        <geom name="sensor_2_case" type="box" pos="0 0 0" size="0.03 0.03 0.06" rgba="0.2 0.4 0.6 1" contype="1" conaffinity="1" />
        <geom name="sensor_2_probe" type="cylinder" pos="0 0 -0.06" size="0.005 0.04" rgba="0.8 0.8 0.8 1" />
    </body>

    
    
    <body name="physics_cabinet_1_body" pos="-5.5 5.25 1.0">
        <geom name="physics_cabinet_1" type="box" pos="0 0 0" size="0.5 0.25 1.0" rgba="0.55 0.45 0.35 1" contype="1" conaffinity="1" />
        <geom name="physics_cabinet_1_door" type="box" pos="0 0.26 0" size="0.48 0.02 0.95" rgba="0.6 0.5 0.4 1" contype="1" conaffinity="1" />
    </body>

    
    <body name="physics_cabinet_2_body" pos="-3.0 5.25 1.0">
        <geom name="physics_cabinet_2" type="box" pos="0 0 0" size="0.5 0.25 1.0" rgba="0.55 0.45 0.35 1" contype="1" conaffinity="1" />
        <geom name="physics_cabinet_2_door" type="box" pos="0 0.26 0" size="0.48 0.02 0.95" rgba="0.6 0.5 0.4 1" contype="1" conaffinity="1" />
    </body>

    
    <body name="physics_aux_table_body" pos="-6.95 9 0.4">
        
        <geom name="physics_aux_table_top" type="box" pos="0 0 0.415" size="0.31 0.76 0.025" rgba="0.35 0.35 0.35 1" contype="1" conaffinity="1" />
        
        <geom name="aux_table_leg_1" type="cylinder" pos="0.25 0.7 -0.005" size="0.04 0.395" rgba="0.45 0.45 0.45 1" />
        <geom name="aux_table_leg_2" type="cylinder" pos="0.25 -0.7 -0.005" size="0.04 0.395" rgba="0.45 0.45 0.45 1" />
        <geom name="aux_table_leg_3" type="cylinder" pos="-0.25 0.7 -0.005" size="0.04 0.395" rgba="0.45 0.45 0.45 1" />
        <geom name="aux_table_leg_4" type="cylinder" pos="-0.25 -0.7 -0.005" size="0.04 0.395" rgba="0.45 0.45 0.45 1" />
    </body>

    
    <body name="aux_tool_box_body" pos="-6.95 8.5 0.89">
        <freejoint />
        
        <geom name="aux_tool_box" type="box" pos="0 0 0" size="0.15 0.1 0.05" rgba="0.2 0.3 0.4 1" contype="1" conaffinity="1" />
        
        <geom name="tool_box_handle" type="box" pos="0 0 0.06" size="0.1 0.01 0.01" rgba="0.1 0.1 0.1 1" />
        <geom name="tool_box_handle_l" type="box" pos="-0.1 0 0.055" size="0.01 0.01 0.015" rgba="0.1 0.1 0.1 1" />
        <geom name="tool_box_handle_r" type="box" pos="0.1 0 0.055" size="0.01 0.01 0.015" rgba="0.1 0.1 0.1 1" />
        
        <geom name="tool_box_latch_1" type="box" pos="-0.05 -0.1 0" size="0.01 0.005 0.02" rgba="0.8 0.8 0.8 1" />
        <geom name="tool_box_latch_2" type="box" pos="0.05 -0.1 0" size="0.01 0.005 0.02" rgba="0.8 0.8 0.8 1" />
    </body>
    <body name="aux_notebook_body" pos="-6.95 9.5 0.85">
        <freejoint />
        
        <geom name="aux_notebook_cover" type="box" pos="0 0 0" size="0.12 0.15 0.01" rgba="0.1 0.2 0.5 1" contype="1" conaffinity="1" />
        
        <geom name="aux_notebook_pages" type="box" pos="0.01 0 0" size="0.11 0.145 0.011" rgba="0.95 0.95 0.9 1" contype="0" conaffinity="0" />
        
        <geom name="aux_notebook_spine" type="cylinder" pos="-0.12 0 0" size="0.012 0.15" euler="90 0 0" rgba="0.1 0.1 0.1 1" />
    </body>

    
    
    <body name="first_aid_kit_body" pos="-7.0 5.5 0.25">
        <freejoint />
        
        <geom name="first_aid_case" type="box" pos="0 0 0" size="0.15 0.1 0.15" rgba="0.9 0.1 0.1 1" contype="1" conaffinity="1" />
        
        <geom name="first_aid_handle" type="cylinder" pos="0 0 0.15" size="0.01 0.06" euler="90 0 0" rgba="0.8 0.8 0.8 1" />
        
        <geom name="fa_cross_v" type="box" pos="0 0.1 0" size="0.04 0.005 0.08" rgba="1 1 1 1" contype="0" conaffinity="0" />
        <geom name="fa_cross_h" type="box" pos="0 0.1 0" size="0.08 0.005 0.04" rgba="1 1 1 1" contype="0" conaffinity="0" />
        
        <geom name="fa_latch_1" type="box" pos="-0.08 0.1 0.12" size="0.01 0.005 0.02" rgba="0.8 0.8 0.8 1" />
        <geom name="fa_latch_2" type="box" pos="0.08 0.1 0.12" size="0.01 0.005 0.02" rgba="0.8 0.8 0.8 1" />
    </body>

    
    <body name="fire_extinguisher_body" pos="-6.9 5.8 0.4">
        <freejoint />
        
        <geom name="fire_ext_tank" type="cylinder" pos="0 0 0" size="0.08 0.3" rgba="0.8 0.1 0.1 1" contype="1" conaffinity="1" />
        
        <geom name="fire_ext_neck" type="cylinder" pos="0 0 0.32" size="0.03 0.05" rgba="0.2 0.2 0.2 1" />
        <geom name="fire_ext_handle" type="box" pos="-0.04 0 0.38" size="0.04 0.01 0.01" rgba="0.8 0.8 0.8 1" />
        <geom name="fire_ext_lever" type="box" pos="-0.04 0 0.35" size="0.04 0.01 0.01" rgba="0.8 0.8 0.8 1" />
        
        <geom name="fire_ext_hose" type="capsule" pos="0.05 0 0.25" size="0.02 0.1" euler="0 45 0" rgba="0.1 0.1 0.1 1" />
        
        <geom name="extinguisher_label" type="box" pos="0.08 0 0.1" size="0.002 0.06 0.1" rgba="1 1 1 1" contype="0" conaffinity="0" />
    </body>

    
    <geom name="power_outlet_1" type="box" pos="-1.3 7 0.3" size="0.03 0.08 0.08" rgba="0.9 0.9 0.9 1" contype="0" conaffinity="0" />
    <geom name="power_outlet_2" type="box" pos="-1.3 11 0.3" size="0.03 0.08 0.08" rgba="0.9 0.9 0.9 1" contype="0" conaffinity="0" />
    <geom name="power_outlet_3" type="box" pos="-7.2 9 0.3" size="0.03 0.08 0.08" rgba="0.9 0.9 0.9 1" contype="0" conaffinity="0" />

    
    

    
    <geom name="chemistry_floor" type="box" pos="4.25 13 0" size="3 5 0.1" material="chem_floor_epoxy" contype="1" conaffinity="1" />
    
    
    <geom name="chemistry_wall_north" type="box" pos="4.25 18 1.6" size="3 0.1 1.6" material="chem_wall_tile" contype="1" conaffinity="1" />
    <geom name="chemistry_wall_east" type="box" pos="7.25 13 1.6" size="0.1 5 1.6" material="chem_wall_tile" contype="1" conaffinity="1" />

    
    <geom name="chemistry_wall_west_1" type="box" pos="1.25 11.2 1.6" size="0.1 3.2 1.6" material="chem_wall_tile" contype="1" conaffinity="1" />
    <geom name="chemistry_wall_west_2" type="box" pos="1.25 16.8 1.6" size="0.1 1.2 1.6" material="chem_wall_tile" contype="1" conaffinity="1" />

    
    <geom name="chemistry_wall_south" type="box" pos="4.25 8 1.6" size="3 0.1 1.6" material="chem_wall_tile" contype="1" conaffinity="1" />

    
    
    
    
    <body name="chemistry_main_table_body" pos="4.25 13 0.3">
        
        <geom name="chemistry_table_top" type="box" pos="0 0 0.425" size="0.51 2.01 0.025" material="granite_mat" contype="1" conaffinity="1" />
        
        <geom name="chem_table_cab_1" type="box" pos="0 1.5 0.1" size="0.45 0.45 0.3" rgba="0.8 0.8 0.8 1" />
        <geom name="chem_table_cab_2" type="box" pos="0 -1.5 0.1" size="0.45 0.45 0.3" rgba="0.8 0.8 0.8 1" />
        <geom name="chem_table_cab_3" type="box" pos="0 0 0.1" size="0.45 0.45 0.3" rgba="0.8 0.8 0.8 1" />
        
        <geom name="chem_table_beam" type="box" pos="0 0 0.38" size="0.4 1.8 0.02" rgba="0.3 0.3 0.3 1" />
        
        <geom name="chem_foot_1" type="cylinder" pos="0.4 1.9 -0.15" size="0.05 0.05" rgba="0.1 0.1 0.1 1" />
        <geom name="chem_foot_2" type="cylinder" pos="-0.4 1.9 -0.15" size="0.05 0.05" rgba="0.1 0.1 0.1 1" />
        <geom name="chem_foot_3" type="cylinder" pos="0.4 -1.9 -0.15" size="0.05 0.05" rgba="0.1 0.1 0.1 1" />
        <geom name="chem_foot_4" type="cylinder" pos="-0.4 -1.9 -0.15" size="0.05 0.05" rgba="0.1 0.1 0.1 1" />
    </body>

    
    <geom name="organic_zone_marker" type="box" pos="4.25 11.5 0.735" size="0.5 1 0.02" material="organic_zone_mat" contype="0" conaffinity="0" />
    
    
    <geom name="inorganic_zone_marker" type="box" pos="4.25 14.5 0.735" size="0.5 1 0.02" material="inorganic_zone_mat" contype="0" conaffinity="0" />

    
    <body name="chemistry_sink_body" pos="4.25 13 0.3">
        <geom name="chemistry_sink" type="box" pos="0 0 0.15" size="0.25 0.2 0.15" material="sink_mat" contype="1" conaffinity="1" />
        <geom name="chemistry_sink_rim" type="box" pos="0 0 0.32" size="0.26 0.21 0.01" rgba="0.5 0.5 0.5 1" contype="1" conaffinity="1" />
        
        <geom name="chem_faucet_v" type="cylinder" pos="0 0.25 0.4" size="0.02 0.15" rgba="0.9 0.9 0.9 1" />
        <geom name="chem_faucet_h" type="cylinder" pos="0 0.1 0.55" size="0.015 0.15" euler="90 0 0" rgba="0.9 0.9 0.9 1" />
        <geom name="chem_faucet_curve" type="capsule" pos="0 0.175 0.525" euler="108.4 0 0" size="0.015 0.079" rgba="0.9 0.9 0.9 1" />
        <geom name="chem_tap_handle" type="box" pos="0.05 0.25 0.35" size="0.01 0.04 0.01" euler="0 45 0" rgba="0.2 0.2 0.8 1" />
    </body>

    
    
    <geom name="chemistry_outlet_1" type="box" pos="4.0 11 0.275" size="0.04 0.1 0.08" rgba="0.8 0.8 0.8 1" contype="0" conaffinity="0" />
    <geom name="chemistry_outlet_2" type="box" pos="4.0 11.8 0.275" size="0.04 0.1 0.08" rgba="0.8 0.8 0.8 1" contype="0" conaffinity="0" />
    <geom name="chemistry_outlet_3" type="box" pos="4.0 12.6 0.275" size="0.04 0.1 0.08" rgba="0.8 0.8 0.8 1" contype="0" conaffinity="0" />
    
    
    <geom name="chemistry_outlet_4" type="box" pos="4.5 13.4 0.275" size="0.04 0.1 0.08" rgba="0.8 0.8 0.8 1" contype="0" conaffinity="0" />
    <geom name="chemistry_outlet_5" type="box" pos="4.5 14.2 0.275" size="0.04 0.1 0.08" rgba="0.8 0.8 0.8 1" contype="0" conaffinity="0" />
    <geom name="chemistry_outlet_6" type="box" pos="4.5 15 0.275" size="0.04 0.1 0.08" rgba="0.8 0.8 0.8 1" contype="0" conaffinity="0" />

    
    
    <body name="hplc_body" pos="4.25 11.5 0.8">
        <freejoint />
        
        <geom name="hplc_base_unit" type="box" pos="0 0 0" size="0.25 0.3 0.05" rgba="0.8 0.8 0.9 1" />
        <geom name="hplc_pump_mod" type="box" pos="0 0 0.1" size="0.25 0.3 0.05" rgba="0.9 0.9 0.95 1" />
        <geom name="hplc_screen" type="box" pos="0 -0.30 0.2" size="0.1 0.01 0.05" rgba="0.2 0.3 0.2 1" /> 
        <geom name="hplc_sampler" type="box" pos="0 0 0.2" size="0.25 0.3 0.05" rgba="0.9 0.9 0.95 1" />
        <geom name="hplc_detector" type="box" pos="0 0 0.3" size="0.25 0.3 0.05" rgba="0.9 0.9 0.95 1" />
        
        <geom name="solv_bottle_1" type="cylinder" pos="-0.15 0 0.45" size="0.04 0.1" rgba="0.6 0.4 0.2 0.5" />
        <geom name="solv_bottle_2" type="cylinder" pos="0 0 0.45" size="0.04 0.1" rgba="0.6 0.4 0.2 0.5" />
        <geom name="solv_bottle_3" type="cylinder" pos="0.15 0 0.45" size="0.04 0.1" rgba="0.6 0.4 0.2 0.5" />
    </body>

    
    <body name="uvvis_body" pos="4.25 14.5 0.9">
        <freejoint />
        
        <geom name="uvvis_case" type="box" pos="0 0 0" size="0.22 0.28 0.15" rgba="0.9 0.9 0.95 1" contype="1" conaffinity="1" />
        
        <geom name="uvvis_lid" type="box" pos="0.1 0.1 0.16" size="0.1 0.15 0.01" euler="0 -20 0" rgba="0.3 0.3 0.3 0.5" />
        
        <geom name="uvvis_screen" type="box" pos="-0.15 -0.2 0.1" size="0.05 0.08 0.05" euler="30 0 0" rgba="0.2 0.2 0.2 1" />
        
        <geom name="uvvis_holder" type="box" pos="0.1 0.1 0.1" size="0.05 0.05 0.04" rgba="0.1 0.1 0.1 1" />
    </body>

    
    <body name="chemistry_data_workstation_body" pos="3.5 8.4 0.375">
        
        <geom name="data_workstation_desk" type="box" pos="0 0 0" size="0.6 0.4 0.375" rgba="0.55 0.55 0.55 1" contype="1" conaffinity="1" />
        
        <geom name="data_workstation_pc_tower" type="box" pos="-0.3 0.1 0.2" size="0.08 0.1 0.2" rgba="0.1 0.1 0.1 1" contype="1" conaffinity="1" />
        <geom name="data_workstation_pc_screen" type="box" pos="-0.05 0.0 0.32" size="0.12 0.02 0.18" rgba="0.15 0.15 0.2 1" contype="1" conaffinity="1" />
        
        <geom name="data_workstation_printer" type="box" pos="0.25 -0.1 0.32" size="0.15 0.12 0.12" rgba="0.8 0.8 0.8 1" contype="1" conaffinity="1" />
        
        <geom name="data_workstation_dms" type="box" pos="0.25 0.15 0.18" size="0.12 0.1 0.08" rgba="0.3 0.4 0.6 1" contype="1" conaffinity="1" />
    </body>
    
    
    
    <body name="ultrasonic_cleaner_body" pos="2.0 9.5 1.13">
        <freejoint />
        
        <geom name="ultra_shell" type="box" pos="0 0 0" size="0.25 0.3 0.2" rgba="0.9 0.9 0.9 1" contype="1" conaffinity="1" />
        
        <geom name="ultra_tank_inner" type="box" pos="0 0 0.05" size="0.2 0.25 0.15" rgba="0.7 0.7 0.7 1" />
        
        <geom name="ultra_lid" type="box" pos="0.26 0 0.2" size="0.01 0.28 0.18" euler="0 10 0" rgba="0.2 0.4 0.8 0.5" />
        
        <geom name="ultra_controls" type="box" pos="-0.25 0 -0.1" size="0.01 0.28 0.08" rgba="0.2 0.2 0.2 1" />
    </body>

    
    <body name="centrifuge_body" pos="2.0 10.25 1.075">
        <freejoint />
        
        <geom name="centrifuge_case" type="cylinder" pos="0 0 0" size="0.2 0.2" rgba="0.9 0.9 0.95 1" contype="1" conaffinity="1" />
        
        <geom name="centrifuge_top_bevel" type="cylinder" pos="0 0 0.15" size="0.18 0.05" rgba="0.8 0.8 0.85 1" />
        
        <geom name="centrifuge_lid_closed" type="cylinder" pos="0 0 0.2" size="0.16 0.02" rgba="0.2 0.2 0.2 0.2" />
        
        <geom name="centrifuge_axis" type="cylinder" pos="0 0 0.1" size="0.02 0.1" rgba="0.1 0.1 0.1 1" /> 
        
        <geom name="cent_button" type="cylinder" pos="0.18 0 0.1" size="0.02 0.01" euler="0 90 0" rgba="0.1 0.8 0.1 1" />
    </body>

    
    <body name="vacuum_dryer_body" pos="2.0 11.0 1.175">
        <freejoint />
        
        <geom name="vac_dryer_case" type="box" pos="0 0 0" size="0.28 0.3 0.3" rgba="0.85 0.85 0.8 1" contype="1" conaffinity="1" />
        
        <geom name="vac_door_frame" type="box" pos="0.28 0 0" size="0.01 0.28 0.28" rgba="0.3 0.3 0.3 1" />
        
        <geom name="vac_door_glass" type="box" pos="0.28 0 0" size="0.01 0.2 0.2" rgba="0.1 0.4 0.6 0.3" />
        
        <geom name="vac_handle" type="box" pos="0.32 0.22 0" size="0.02 0.02 0.05" rgba="0.1 0.1 0.1 1" />
        
        <geom name="vac_gauge_dial" type="cylinder" pos="0.15 0.3 0.2" size="0.04 0.01" euler="90 0 0" rgba="1 1 1 1" />
        <geom name="vac_gauge_rim" type="cylinder" pos="0.15 0.3 0.2" size="0.045 0.005" euler="90 0 0" rgba="0.1 0.1 0.1 1" />
    </body>

    
    <body name="ultrapure_water_body" pos="2.0 11.75 1.275">
        <freejoint />
        
        <geom name="water_system_case" type="box" pos="0 0 0" size="0.2 0.32 0.4" rgba="0.9 0.9 0.95 1" contype="1" conaffinity="1" />
        
        <geom name="water_panel_blue" type="box" pos="-0.1 0 0" size="0.1 0.32 0.38" rgba="0.1 0.3 0.8 1" contype="0" conaffinity="0" />
        <geom name="water_screen" type="box" pos="-0.21 0 0.2" size="0.01 0.1 0.08" rgba="0.1 0.1 0.1 1" />
        
        <geom name="cartridge_1" type="cylinder" pos="0.1 0.15 -0.1" size="0.06 0.25" rgba="1 1 1 0.8" />
        <geom name="cartridge_2" type="cylinder" pos="0.1 -0.15 -0.1" size="0.06 0.25" rgba="1 1 1 0.8" />
        
        <geom name="water_dispenser_arm" type="capsule" pos="-0.2 0 -0.25" euler="0 -116.6 0" size="0.02 0.112" rgba="0.7 0.7 0.7 1" />
        <geom name="water_nozzle" type="cylinder" pos="-0.3 0 -0.32" size="0.015 0.02" rgba="1 1 1 1" />
    </body>

    
    
    <body name="chemistry_side_table_1_body" pos="2.0 10.5 0.425">
        
        <geom name="chemistry_side_table_1_top" type="box" pos="0 0 0.425" size="0.36 2.26 0.025" material="granite_mat" contype="1" conaffinity="1" />
        
        <geom name="side_cab_1a" type="box" pos="0 1.5 0" size="0.3 0.7 0.4" rgba="0.8 0.8 0.8 1" />
        <geom name="side_cab_1b" type="box" pos="0 0 0" size="0.3 0.7 0.4" rgba="0.8 0.8 0.8 1" /> 
        <geom name="side_cab_1c" type="box" pos="0 -1.5 0" size="0.3 0.7 0.4" rgba="0.8 0.8 0.8 1" />
        
        <geom name="side_toe_kick_1" type="box" pos="-0.05 0 -0.38" size="0.25 2.2 0.02" rgba="0.2 0.2 0.2 1" />
        
        <geom name="side_handle_1a" type="box" pos="0.31 1.5 0.2" size="0.01 0.1 0.01" rgba="0.6 0.6 0.6 1" />
        <geom name="side_handle_1b" type="box" pos="0.31 0 0.2" size="0.01 0.1 0.01" rgba="0.6 0.6 0.6 1" />
        <geom name="side_handle_1c" type="box" pos="0.31 -1.5 0.2" size="0.01 0.1 0.01" rgba="0.6 0.6 0.6 1" />
    </body>

    
    <body name="reagent_rack_body" pos="1.5 10.5 0.85">
        <freejoint />
        
        <geom name="rack_frame_l" type="box" pos="0 0.48 0" size="0.14 0.02 0.3" rgba="0.6 0.6 0.65 1" contype="1" conaffinity="1" />
        <geom name="rack_frame_r" type="box" pos="0 -0.48 0" size="0.14 0.02 0.3" rgba="0.6 0.6 0.65 1" contype="1" conaffinity="1" />
        
        <geom name="rack_shelf_1" type="box" pos="0 0 -0.15" size="0.13 0.46 0.005" rgba="0.9 0.9 0.9 0.5" />
        <geom name="rack_shelf_2" type="box" pos="0 0 0.0" size="0.13 0.46 0.005" rgba="0.9 0.9 0.9 0.5" />
        <geom name="rack_shelf_3" type="box" pos="0 0 0.15" size="0.13 0.46 0.005" rgba="0.9 0.9 0.9 0.5" />
        
        <geom name="bottle_group_1" type="cylinder" pos="0 0.2 0.05" size="0.03 0.04" rgba="0.6 0.3 0.1 1" />
        <geom name="bottle_group_2" type="cylinder" pos="0 -0.2 0.05" size="0.03 0.04" rgba="0.6 0.3 0.1 1" />
        <geom name="bottle_group_3" type="cylinder" pos="0 0 0.2" size="0.03 0.04" rgba="0.2 0.3 0.6 1" />
    </body>
    
    <geom name="sample_prep_outlet_1" type="box" pos="1.5 9 0.5" size="0.04 0.1 0.08" rgba="0.8 0.8 0.8 1" contype="0" conaffinity="0" />
    <geom name="sample_prep_outlet_2" type="box" pos="1.5 10.5 0.5" size="0.04 0.1 0.08" rgba="0.8 0.8 0.8 1" contype="0" conaffinity="0" />
    <geom name="sample_prep_outlet_3" type="box" pos="1.5 12 0.5" size="0.04 0.1 0.08" rgba="0.8 0.8 0.8 1" contype="0" conaffinity="0" />

    
    <body name="chemistry_side_table_2_body" pos="6.5 13 0.425">
        
        <geom name="chemistry_side_table_2_top" type="box" pos="0 0 0.425" size="0.36 2.26 0.025" material="granite_mat" contype="1" conaffinity="1" />
        
        <geom name="side_cab_2a" type="box" pos="0 1.5 0" size="0.3 0.7 0.4" rgba="0.8 0.8 0.8 1" />
        <geom name="side_cab_2b" type="box" pos="0 0 0" size="0.3 0.7 0.4" rgba="0.8 0.8 0.8 1" /> 
        <geom name="side_cab_2c" type="box" pos="0 -1.5 0" size="0.3 0.7 0.4" rgba="0.8 0.8 0.8 1" />
        
        <geom name="side_toe_kick_2" type="box" pos="0.05 0 -0.38" size="0.25 2.2 0.02" rgba="0.2 0.2 0.2 1" />
        
        <geom name="side_handle_2a" type="box" pos="-0.31 1.5 0.2" size="0.01 0.1 0.01" rgba="0.6 0.6 0.6 1" />
        <geom name="side_handle_2b" type="box" pos="-0.31 0 0.2" size="0.01 0.1 0.01" rgba="0.6 0.6 0.6 1" />
        <geom name="side_handle_2c" type="box" pos="-0.31 -1.5 0.2" size="0.01 0.1 0.01" rgba="0.6 0.6 0.6 1" />
    </body>

    
    <geom name="instr_power_1" type="box" pos="7.0 10.6 0.5" size="0.08 0.12 0.1" rgba="0.8 0.2 0.2 1" contype="0" conaffinity="0" />
    <geom name="instr_power_2" type="box" pos="7.0 13 0.5" size="0.08 0.12 0.1" rgba="0.8 0.2 0.2 1" contype="0" conaffinity="0" />
    <geom name="instr_power_3" type="box" pos="7.0 16 0.5" size="0.08 0.12 0.1" rgba="0.8 0.2 0.2 1" contype="0" conaffinity="0" />

    
    <geom name="instr_data_1" type="box" pos="6.8 10.6 0.5" size="0.06 0.1 0.08" rgba="0.2 0.8 0.2 1" contype="0" conaffinity="0" />
    <geom name="instr_data_2" type="box" pos="6.8 13 0.5" size="0.06 0.1 0.08" rgba="0.2 0.8 0.2 1" contype="0" conaffinity="0" />
    <geom name="instr_data_3" type="box" pos="6.8 16 0.5" size="0.06 0.1 0.08" rgba="0.2 0.8 0.2 1" contype="0" conaffinity="0" />

    
    
    <body name="chemistry_overhead_cabinet_1_body" pos="2.0 10.5 2.0">
        
        <geom name="chem_cabinet_1_body" type="box" pos="0 0 0" size="0.35 2.25 0.3" rgba="0.7 0.7 0.6 1" contype="1" conaffinity="1" />
        
        <geom name="chem_cabinet_1_door_front" type="box" pos="-0.18 0 0" size="0.05 2.26 0.3" rgba="0.75 0.75 0.65 1" contype="1" conaffinity="1" />
        <geom name="chem_cabinet_1_door_back" type="box" pos="0.18 0 0" size="0.05 2.26 0.3" rgba="0.75 0.75 0.65 1" contype="1" conaffinity="1" />
        
        <geom name="chemistry_hvac_vent_west" type="box" pos="0 0 -0.35" size="0.05 1.0 0.05" material="hvac_vent_mat" contype="0" conaffinity="0" />
    </body>

    
    <body name="chemistry_overhead_cabinet_2_body" pos="6.5 13 2.0">
        
        <geom name="chem_cabinet_2_body" type="box" pos="0 0 0" size="0.35 2.25 0.3" rgba="0.7 0.7 0.6 1" contype="1" conaffinity="1" />
        
        <geom name="chem_cabinet_2_door_front" type="box" pos="-0.18 0 0" size="0.05 2.26 0.3" rgba="0.75 0.75 0.65 1" contype="1" conaffinity="1" />
        <geom name="chem_cabinet_2_door_back" type="box" pos="0.18 0 0" size="0.05 2.26 0.3" rgba="0.75 0.75 0.65 1" contype="1" conaffinity="1" />
        
        <geom name="chemistry_hvac_vent_east" type="box" pos="0 0 -0.35" size="0.05 1.0 0.05" material="hvac_vent_mat" contype="0" conaffinity="0" />
    </body>

    
    <geom name="chemistry_marker" type="box" pos="4.25 13 0.075" size="0.5 0.3 0.05" rgba="0.9 0.7 0.6 1" contype="0" conaffinity="0" />

    
    
    <body name="fume_hood_1_body" pos="5.5 18.5 1.25">
        <geom name="fume_hood_1_frame" type="box" pos="0 0 0" size="0.45 0.45 1.25" material="fume_hood_frame" contype="1" conaffinity="1" />
        <geom name="fume_hood_1_front" type="box" pos="0 -0.46 0.5" size="0.44 0.02 0.8" material="fume_hood_glass" contype="1" conaffinity="1" />
        
        <geom name="fume_hood_1_sink" type="box" pos="0 0.2 -1.1" size="0.35 0.3 0.15" rgba="0.5 0.5 0.5 1" contype="1" conaffinity="1" />
        
        <geom name="fume_hood_1_shelf_1" type="box" pos="0 0 -0.6" size="0.43 0.42 0.03" material="corrosion_shelf" contype="1" conaffinity="1" />
        <geom name="fume_hood_1_shelf_2" type="box" pos="0 0 -0.1" size="0.43 0.42 0.03" material="corrosion_shelf" contype="1" conaffinity="1" />
        
        <geom name="fume_hood_1_duct" type="cylinder" pos="0 0 1.3" size="0.1 0.2" rgba="0.3 0.3 0.3 1" contype="0" conaffinity="0" />
    </body>

    
    <body name="fume_hood_2_body" pos="6.5 18.5 1.25">
        <geom name="fume_hood_2_frame" type="box" pos="0 0 0" size="0.45 0.45 1.25" material="fume_hood_frame" contype="1" conaffinity="1" />
        <geom name="fume_hood_2_front" type="box" pos="0 -0.46 0.5" size="0.44 0.02 0.8" material="fume_hood_glass" contype="1" conaffinity="1" />
        
        <geom name="fume_hood_2_sink" type="box" pos="0 0.2 -1.1" size="0.35 0.3 0.15" rgba="0.5 0.5 0.5 1" contype="1" conaffinity="1" />
        
        <geom name="fume_hood_2_shelf_1" type="box" pos="0 0 -0.6" size="0.43 0.42 0.03" material="corrosion_shelf" contype="1" conaffinity="1" />
        <geom name="fume_hood_2_shelf_2" type="box" pos="0 0 -0.1" size="0.43 0.42 0.03" material="corrosion_shelf" contype="1" conaffinity="1" />
        
        <geom name="acid_neutralizer" type="box" pos="0 -0.3 1.2" size="0.35 0.2 0.15" rgba="0.7 0.5 0.3 1" contype="1" conaffinity="1" />
        
        <geom name="fume_hood_2_duct" type="cylinder" pos="0 0 1.3" size="0.1 0.2" rgba="0.3 0.3 0.3 1" contype="0" conaffinity="0" />
    </body>
    
    
    <body name="chemistry_hvac_main_body" pos="2.0 18.5 1.0">
        
        <geom name="chemistry_hvac_main" type="box" pos="0 0 0" size="0.7 0.4 1.0" material="hvac_unit_mat" contype="1" conaffinity="1" />
        
        <geom name="chemistry_hvac_panel" type="box" pos="0.72 0 0.4" size="0.02 0.3 0.25" rgba="0.2 0.3 0.35 1" contype="0" conaffinity="0" />
        
        <geom name="chemistry_hvac_duct_outdoor" type="cylinder" pos="0 0 1.0" size="0.12 0.6" rgba="0.5 0.5 0.5 1" contype="0" conaffinity="0" />
    </body>
    
    
    <body name="aa_hood_body" pos="4.25 13 2.5">
        
        <geom name="aa_hood_main" type="cylinder" pos="0 0 0" size="0.3 0.4" rgba="0.4 0.4 0.4 1" contype="1" conaffinity="1" />
        
        <geom name="aa_hood_inlet" type="cylinder" pos="0 0 -0.35" size="0.31 0.05" rgba="0.3 0.3 0.3 1" contype="0" conaffinity="0" />
        
        <geom name="aa_hood_duct" type="cylinder" pos="0 0 0.4" size="0.08 0.3" rgba="0.3 0.3 0.3 1" contype="0" conaffinity="0" />
    </body>

    
    
    <body name="suction_hood_1_body" pos="3.5 12 2.8">
        <geom name="suction_hood_1" type="cylinder" pos="0 0 0" size="0.15 0.2" rgba="0.5 0.5 0.6 1" contype="1" conaffinity="1" />
        <geom name="suction_hood_1_arm" type="cylinder" pos="0 -0.15 0.3" size="0.02 0.4" rgba="0.3 0.3 0.3 1" contype="1" conaffinity="1" />
    </body>

    
    <body name="suction_hood_2_body" pos="5 14 2.8">
        <geom name="suction_hood_2" type="cylinder" pos="0 0 0" size="0.15 0.2" rgba="0.5 0.5 0.6 1" contype="1" conaffinity="1" />
        <geom name="suction_hood_2_arm" type="cylinder" pos="0 0.15 0.3" size="0.02 0.4" rgba="0.3 0.3 0.3 1" contype="1" conaffinity="1" />
    </body>

    
    <body name="suction_hood_3_body" pos="2 9.5 2.7">
        <geom name="suction_hood_3" type="cylinder" pos="0 0 0" size="0.15 0.2" rgba="0.5 0.5 0.6 1" contype="1" conaffinity="1" />
        <geom name="suction_hood_3_arm" type="cylinder" pos="0.15 0 0.3" size="0.02 0.4" rgba="0.3 0.3 0.3 1" contype="1" conaffinity="1" />
    </body>

    
    <body name="suction_hood_4_body" pos="2 11.5 2.7">
        <geom name="suction_hood_4" type="cylinder" pos="0 0 0" size="0.15 0.2" rgba="0.5 0.5 0.6 1" contype="1" conaffinity="1" />
        <geom name="suction_hood_4_arm" type="cylinder" pos="0.15 0 0.3" size="0.02 0.4" rgba="0.3 0.3 0.3 1" contype="1" conaffinity="1" />
    </body>

    
    <body name="suction_hood_5_body" pos="6.5 11 2.7">
        <geom name="suction_hood_5" type="cylinder" pos="0 0 0" size="0.15 0.2" rgba="0.5 0.5 0.6 1" contype="1" conaffinity="1" />
        <geom name="suction_hood_5_arm" type="cylinder" pos="-0.15 0 0.3" size="0.02 0.4" rgba="0.3 0.3 0.3 1" contype="1" conaffinity="1" />
    </body>

    
    <body name="suction_hood_6_body" pos="6.5 15 2.7">
        <geom name="suction_hood_6" type="cylinder" pos="0 0 0" size="0.15 0.2" rgba="0.5 0.5 0.6 1" contype="1" conaffinity="1" />
        <geom name="suction_hood_6_arm" type="cylinder" pos="-0.15 0 0.3" size="0.02 0.4" rgba="0.3 0.3 0.3 1" contype="1" conaffinity="1" />
    </body>

    
    
    
    
    <body name="reagent_cabinet_1_body" pos="1.8 17.3 0.9">
        
        <geom name="reagent_cabinet_1_main" type="box" pos="0 0 0" size="0.5 0.25 0.9" rgba="0.6 0.4 0.3 1" contype="1" conaffinity="1" />
        
        <geom name="reagent_cabinet_1_door" type="box" pos="0.26 0 0" size="0.02 0.24 0.85" rgba="0.65 0.45 0.35 1" contype="1" conaffinity="1" />
        
        <geom name="reagent_cabinet_1_indicator" type="cylinder" pos="-0.2 0.1 0.7" size="0.02 0.05" rgba="0.1 0.8 0.1 1" contype="0" conaffinity="0" />
    </body>

    
    <body name="sample_cabinet_1_body" pos="2.95 17.3 0.9">
        
        <geom name="sample_cabinet_1_main" type="box" pos="0 0 0" size="0.5 0.25 0.9" rgba="0.3 0.3 0.4 1" contype="1" conaffinity="1" />
        
        <geom name="sample_cabinet_1_door" type="box" pos="0.26 0 0" size="0.02 0.24 0.85" rgba="0.2 0.2 0.2 1" contype="1" conaffinity="1" />
        
        <geom name="sample_cabinet_1_indicator" type="box" pos="-0.2 0.1 0.7" size="0.08 0.1 0.15" rgba="0.1 0.1 0.1 1" contype="0" conaffinity="0" />
    </body>

    
    <body name="reagent_cabinet_2_body" pos="4.1 17.3 0.9">
        
        <geom name="reagent_cabinet_2_main" type="box" pos="0 0 0" size="0.5 0.25 0.9" rgba="0.6 0.4 0.3 1" contype="1" conaffinity="1" />
        
        <geom name="reagent_cabinet_2_door" type="box" pos="0.26 0 0" size="0.02 0.24 0.85" rgba="0.65 0.45 0.35 1" contype="1" conaffinity="1" />
        
        <geom name="reagent_cabinet_2_label" type="box" pos="-0.2 0 0.5" size="0.08 0.15 0.3" rgba="0.9 0.3 0.1 1" contype="0" conaffinity="0" />
    </body>

    
    <body name="sample_cabinet_2_body" pos="5.25 17.3 0.9">
        
        <geom name="sample_cabinet_2_main" type="box" pos="0 0 0" size="0.5 0.25 0.9" rgba="0.3 0.4 0.6 1" contype="1" conaffinity="1" />
        
        <geom name="sample_cabinet_2_door" type="box" pos="0.26 0 0" size="0.02 0.24 0.85" rgba="0.2 0.3 0.5 1" contype="1" conaffinity="1" />
        
        <geom name="sample_cabinet_2_frost" type="box" pos="-0.2 0.1 0.7" size="0.08 0.1 0.15" rgba="0.7 0.8 0.9 0.5" contype="0" conaffinity="0" />
    </body>

    
    <body name="reagent_cabinet_3_body" pos="6.4 17.3 0.9">
        
        <geom name="reagent_cabinet_3_main" type="box" pos="0 0 0" size="0.5 0.25 0.9" rgba="0.6 0.4 0.3 1" contype="1" conaffinity="1" />
        
        <geom name="reagent_cabinet_3_door" type="box" pos="0.26 0 0" size="0.02 0.24 0.85" rgba="0.65 0.45 0.35 1" contype="1" conaffinity="1" />
        
        <geom name="reagent_cabinet_3_label" type="box" pos="-0.2 0 0.5" size="0.08 0.15 0.3" rgba="0.3 0.3 0.8 1" contype="0" conaffinity="0" />
    </body>

    
    
    
    
    
    
    <body name="waste_acid_drum_body" pos="6.9 8.5 0.35">
        <geom name="waste_acid_drum" type="cylinder" pos="0 0 0" size="0.18 0.35" rgba="0.9 0.2 0.2 1" contype="1" conaffinity="1" />
        
        <geom name="waste_acid_label" type="box" pos="0.18 0 0.15" size="0.02 0.15 0.2" rgba="1 1 1 1" contype="0" conaffinity="0" />
    </body>

    
    <body name="waste_alkali_drum_body" pos="6.9 9.0 0.35">
        <geom name="waste_alkali_drum" type="cylinder" pos="0 0 0" size="0.18 0.35" rgba="0.3 0.3 0.8 1" contype="1" conaffinity="1" />
        
        <geom name="waste_alkali_label" type="box" pos="0.18 0 0.15" size="0.02 0.15 0.2" rgba="1 1 1 1" contype="0" conaffinity="0" />
    </body>

    
    <body name="waste_organic_drum_body" pos="6.9 9.5 0.35">
        <geom name="waste_organic_drum" type="cylinder" pos="0 0 0" size="0.18 0.35" rgba="0.8 0.6 0.2 1" contype="1" conaffinity="1" />
        
        <geom name="waste_organic_label" type="box" pos="0.18 0 0.15" size="0.02 0.15 0.2" rgba="1 1 1 1" contype="0" conaffinity="0" />
    </body>

    
    <body name="waste_heavy_metal_drum_body" pos="6.9 10.0 0.35">
        <geom name="waste_heavy_metal_drum" type="cylinder" pos="0 0 0" size="0.18 0.35" rgba="0.5 0.2 0.6 1" contype="1" conaffinity="1" />
        
        <geom name="waste_heavy_metal_label" type="box" pos="0.18 0 0.15" size="0.02 0.15 0.2" rgba="1 1 1 1" contype="0" conaffinity="0" />
    </body>

    
    <body name="waste_storage_cabinet_body" pos="6.0 8.5 0.5">
        
        <geom name="waste_storage_cabinet_main" type="box" pos="0 0 0" size="0.5 0.3 0.5" rgba="0.4 0.3 0.3 1" contype="1" conaffinity="1" />
        
        <geom name="waste_storage_cabinet_door" type="box" pos="0.26 0 0" size="0.02 0.28 0.48" rgba="0.8 0.4 0 1" contype="1" conaffinity="1" />
        
        <geom name="waste_storage_cabinet_stripe_1" type="box" pos="-0.2 0 0.2" size="0.08 0.28 0.08" rgba="0 0 0 1" contype="0" conaffinity="0" />
        <geom name="waste_storage_cabinet_stripe_2" type="box" pos="-0.2 0 0.35" size="0.08 0.28 0.08" rgba="1 1 0 1" contype="0" conaffinity="0" />
    </body>

    
    

    
    <geom name="biology_floor" type="box" pos="4.75 4 0" size="3.5 4 0.1" material="floor_mat" rgba="0.7 0.9 0.7 0.3" contype="1" conaffinity="1" />

    
    <geom name="biology_wall_south" type="box" pos="4.75 0 1.6" size="3.5 0.1 1.6" material="wall_mat" contype="1" conaffinity="1" />
    <geom name="biology_wall_east" type="box" pos="8.25 4 1.6" size="0.1 4 1.6" material="wall_mat" contype="1" conaffinity="1" />

    
    <geom name="biology_wall_west_1" type="box" pos="1.25 1.7 1.6" size="0.1 1.7 1.6" material="wall_mat" contype="1" conaffinity="1" />
    <geom name="biology_wall_west_2" type="box" pos="1.25 6.3 1.6" size="0.1 1.7 1.6" material="wall_mat" contype="1" conaffinity="1" />

    
    <geom name="biology_wall_north" type="box" pos="4.75 8 1.6" size="3.5 0.1 1.6" material="wall_mat" contype="1" conaffinity="1" />

    
    <geom name="biology_marker" type="box" pos="4.75 4 0.075" size="0.5 0.3 0.05" rgba="0.7 0.9 0.7 1" contype="0" conaffinity="0" />

    

    
    <body name="biology_washbasin_body" pos="1.8 3.0 0.4">
        <geom name="bio_sink_cabinet" type="box" pos="0 0 0" size="0.3 0.25 0.4" rgba="0.9 0.9 0.9 1" contype="1" conaffinity="1" />
        <geom name="bio_sink_basin" type="box" pos="0 0 0.35" size="0.25 0.2 0.05" rgba="0.8 0.8 0.8 1" contype="1" conaffinity="1" />
        <geom name="bio_faucet_body" type="cylinder" pos="0 0.22 0.45" size="0.02 0.1" rgba="0.7 0.7 0.7 1" />
        <geom name="bio_faucet_spout" type="capsule" pos="0 0.15 0.55" euler="110 0 0" size="0.015 0.08" rgba="0.7 0.7 0.7 1" />
    </body>

    
    <body name="biology_hand_dryer_body" pos="1.3 3.3 1.6">
        <geom name="bio_hand_dryer_main" type="box" pos="0 0 0" size="0.15 0.1 0.25" rgba="0.95 0.95 0.95 1" contype="0" conaffinity="0" />
        <geom name="bio_hd_vent" type="box" pos="0.12 0 -0.15" size="0.03 0.08 0.05" rgba="0.2 0.2 0.2 1" />
    </body>

    
    <body name="biology_shoe_cover_body" pos="1.8 4.9 0.2">
        <geom name="bio_shoe_disp_main" type="box" pos="0 0 0" size="0.25 0.15 0.2" rgba="0.6 0.6 0.7 1" contype="1" conaffinity="1" />
        <geom name="bio_shoe_opening" type="box" pos="0 0 0.2" size="0.2 0.1 0.01" rgba="0.1 0.1 0.1 1" />
        <geom name="bio_shoe_handle" type="cylinder" pos="0 0.15 0.1" size="0.02 0.2" euler="90 0 0" rgba="0.8 0.8 0.8 1" />
    </body>

    

    
    <body name="biology_bsc_body" pos="7.8 2.0 1.0">
        
        <geom name="bio_bsc_shell" type="box" pos="0 0 0" size="0.4 0.7 1.0" rgba="0.9 0.9 0.92 1" contype="1" conaffinity="1" />
        
        <geom name="bio_bsc_glass" type="box" pos="-0.4 0 0.2" size="0.02 0.65 0.4" euler="0 -5 0" rgba="0.6 0.8 0.9 0.3" contype="0" conaffinity="0" />
        
        <geom name="bio_bsc_surface" type="box" pos="-0.1 0 -0.1" size="0.3 0.68 0.02" rgba="0.7 0.7 0.7 1" />
        
        <geom name="bio_bsc_filter" type="box" pos="0 0 0.8" size="0.38 0.68 0.18" rgba="0.8 0.8 0.85 1" />
        
        <geom name="bio_bsc_panel" type="box" pos="-0.4 0 0.7" size="0.02 0.68 0.1" rgba="0.2 0.2 0.25 1" />
        
        <geom name="bio_pipettes" type="box" pos="-0.2 -0.4 0.1" size="0.05 0.1 0.1" rgba="0.5 0.5 0.6 1" />
    </body>

    
    <body name="biology_aux_table_body" pos="6.0 2.0 0.4">
        <geom name="bio_aux_table_cab" type="box" pos="0 0 0" size="0.3 0.75 0.4" rgba="0.7 0.7 0.7 1" contype="1" conaffinity="1" />
        <geom name="bio_aux_table_top" type="box" pos="0 0 0.42" size="0.32 0.76 0.02" rgba="0.6 0.6 0.6 1" contype="1" conaffinity="1" />
        <geom name="bio_aux_handle" type="box" pos="-0.31 0 0.2" size="0.01 0.1 0.01" rgba="0.5 0.5 0.5 1" />
    </body>

    
    <body name="biology_cell_counter_body" pos="6.0 2.0 1.04">
        <geom name="bio_counter_body" type="box" pos="0 0 0" size="0.15 0.15 0.2" rgba="0.3 0.3 0.4 1" contype="1" conaffinity="1" />
        <geom name="bio_counter_screen" type="box" pos="-0.15 0 0.05" size="0.01 0.12 0.08" euler="0 -20 0" rgba="0.1 0.1 0.1 1" />
        <geom name="bio_counter_slot" type="box" pos="-0.12 0 -0.1" size="0.05 0.08 0.01" rgba="0.2 0.2 0.2 1" />
    </body>

    
    <body name="biology_aux_centrifuge_body" pos="6.0 2.5 0.99">
        <geom name="bio_bench_cent_body" type="box" pos="0 0 0" size="0.2 0.2 0.15" rgba="0.5 0.5 0.55 1" contype="1" conaffinity="1" />
        <geom name="bio_bench_cent_lid" type="cylinder" pos="0 0 0.15" size="0.18 0.05" rgba="0.6 0.6 0.65 1" />
        <geom name="bio_bench_cent_panel" type="box" pos="-0.2 0 0" size="0.02 0.15 0.05" euler="0 -30 0" rgba="0.2 0.2 0.2 1" />
    </body>

    

    
    <body name="biology_incubator_37_body" pos="7.8 4.0 0.4">
        <geom name="bio_inc_37_main" type="box" pos="0 0 0" size="0.3 0.25 0.4" rgba="0.85 0.85 0.9 1" contype="1" conaffinity="1" />
        <geom name="bio_inc_37_door" type="box" pos="-0.31 0 0" size="0.01 0.24 0.38" rgba="0.9 0.9 0.95 1" />
        <geom name="bio_inc_37_window" type="box" pos="-0.32 0 0.05" size="0.01 0.15 0.2" rgba="0.2 0.2 0.3 0.3" />
        <geom name="bio_inc_37_handle" type="box" pos="-0.33 0.2 0" size="0.02 0.02 0.08" rgba="0.5 0.5 0.5 1" />
        <geom name="bio_inc_37_disp" type="box" pos="-0.32 -0.15 0.3" size="0.01 0.06 0.03" rgba="0.1 0.8 0.1 1" />
    </body>

    
    <body name="biology_incubator_co2_body" pos="7.8 5.2 0.5">
        <geom name="bio_inc_co2_main" type="box" pos="0 0 0" size="0.35 0.3 0.5" rgba="0.8 0.85 0.9 1" contype="1" conaffinity="1" />
        <geom name="bio_inc_co2_door" type="box" pos="-0.36 0 0" size="0.01 0.3 0.48" rgba="0.9 0.9 0.95 1" />
        <geom name="bio_inc_co2_glass" type="box" pos="-0.37 0 0.1" size="0.01 0.2 0.25" rgba="0.1 0.1 0.1 0.8" />
        <geom name="bio_inc_co2_screen" type="box" pos="-0.37 0 0.4" size="0.01 0.1 0.05" rgba="0.2 0.2 0.8 1" />
    </body>

    
    <body name="biology_fridge_4c_body" pos="2.0 7.7 0.9">
        <geom name="bio_fridge_case" type="box" pos="0 0 0" size="0.4 0.3 0.9" rgba="0.85 0.9 0.95 1" contype="1" conaffinity="1" />
        <geom name="bio_fridge_door_top" type="box" pos="-0.02 0 0.25" size="0.4 0.3 0.6" rgba="0.9 0.95 1 1" />
        <geom name="bio_fridge_door_bottom" type="box" pos="-0.02 0 -0.65" size="0.4 0.3 0.25" rgba="0.9 0.95 1 1" />
        <geom name="bio_fridge_handle_1" type="box" pos="-0.42 0.2 0.3" size="0.02 0.02 0.15" rgba="0.7 0.7 0.7 1" />
        <geom name="bio_fridge_handle_2" type="box" pos="-0.42 0.2 -0.5" size="0.02 0.02 0.15" rgba="0.7 0.7 0.7 1" />
    </body>

    
    <body name="biology_freezer_minus20_body" pos="3.2 7.7 0.9">
        <geom name="bio_freezer_20_case" type="box" pos="0 0 0" size="0.4 0.3 0.9" rgba="0.8 0.85 0.9 1" contype="1" conaffinity="1" />
        <geom name="bio_freezer_20_door" type="box" pos="-0.41 0 0" size="0.02 0.3 0.9" rgba="0.9 0.95 1 1" />
        <geom name="bio_freezer_20_handle" type="box" pos="-0.44 0.25 0.1" size="0.02 0.02 0.2" rgba="0.6 0.6 0.6 1" />
        <geom name="bio_freezer_20_disp" type="box" pos="-0.42 0 0.8" size="0.01 0.08 0.04" rgba="0.8 0.2 0.2 1" />
    </body>

    
    <body name="biology_freezer_minus80_body" pos="7.0 7.8 1.0">
        <geom name="bio_freezer_80_case" type="box" pos="0 0 0" size="0.5 0.35 1.0" rgba="0.75 0.8 0.9 1" contype="1" conaffinity="1" />
        <geom name="bio_freezer_80_door" type="box" pos="-0.51 0 0.1" size="0.02 0.35 0.8" rgba="0.9 0.95 1 1" />
        <geom name="bio_freezer_80_vent" type="box" pos="-0.51 0 -0.8" size="0.02 0.35 0.15" rgba="0.3 0.3 0.3 1" />
        <geom name="bio_freezer_80_handle" type="cylinder" pos="-0.55 0.2 0.2" size="0.03 0.15" rgba="0.6 0.6 0.6 1" />
        <geom name="bio_freezer_80_latch" type="box" pos="-0.53 0.2 0.2" size="0.04 0.04 0.08" rgba="0.2 0.2 0.2 1" />
    </body>

    
    <body name="biology_reagent_cabinet_body" pos="4.5 7.7 0.9">
        <geom name="bio_ragent_cab_case" type="box" pos="0 0 0" size="0.6 0.3 0.9" rgba="0.7 0.7 0.7 1" contype="1" conaffinity="1" />
        
        <geom name="bio_ragent_door_l" type="box" pos="-0.29 -0.32 0" size="0.29 0.02 0.88" rgba="0.6 0.8 1 0.4" />
        <geom name="bio_ragent_door_r" type="box" pos="0.29 -0.32 0" size="0.29 0.02 0.88" rgba="0.6 0.8 1 0.4" />
        
        <geom name="bio_ragent_shelf_1" type="box" pos="0 0 -0.4" size="0.58 0.25 0.01" rgba="0.8 0.8 0.8 1" />
        <geom name="bio_ragent_shelf_2" type="box" pos="0 0 0" size="0.58 0.25 0.01" rgba="0.8 0.8 0.8 1" />
        <geom name="bio_ragent_shelf_3" type="box" pos="0 0 0.4" size="0.58 0.25 0.01" rgba="0.8 0.8 0.8 1" />
        
        <geom name="bio_ragent_control" type="box" pos="0 -0.32 0.8" size="0.15 0.03 0.08" rgba="0.2 0.2 0.2 1" />
    </body>

    
    <body name="biology_sample_rack_body" pos="5.8 7.6 0.9">
        <geom name="bio_rack_frame_l" type="box" pos="-0.48 0 0" size="0.02 0.2 0.9" rgba="0.6 0.6 0.65 1" contype="1" conaffinity="1" />
        <geom name="bio_rack_frame_r" type="box" pos="0.48 0 0" size="0.02 0.2 0.9" rgba="0.6 0.6 0.65 1" contype="1" conaffinity="1" />
        <geom name="bio_rack_shelf_1" type="box" pos="0 0 -0.3" size="0.46 0.19 0.01" rgba="0.8 0.8 0.8 1" />
        <geom name="bio_rack_shelf_2" type="box" pos="0 0 0" size="0.46 0.19 0.01" rgba="0.8 0.8 0.8 1" />
        <geom name="bio_rack_shelf_3" type="box" pos="0 0 0.3" size="0.46 0.19 0.01" rgba="0.8 0.8 0.8 1" />
        <geom name="bio_rack_shelf_4" type="box" pos="0 0 0.6" size="0.46 0.19 0.01" rgba="0.8 0.8 0.8 1" />
        
        <geom name="bio_sample_box_1" type="box" pos="-0.2 0 0.05" size="0.1 0.1 0.04" rgba="0.9 0.9 0.8 1" />
        <geom name="bio_sample_box_2" type="box" pos="0.2 0 0.05" size="0.1 0.1 0.04" rgba="0.9 0.9 0.8 1" />
    </body>

    
    <body name="biology_ln2_tank_body" pos="7.8 7.5 0.6">
        <geom name="bio_ln2_body" type="cylinder" pos="0 0 -0.1" size="0.25 0.5" rgba="0.8 0.85 0.9 1" contype="1" conaffinity="1" />
        <geom name="bio_ln2_neck" type="cylinder" pos="0 0 0.45" size="0.1 0.1" rgba="0.5 0.5 0.5 1" />
        <geom name="bio_ln2_cap" type="cylinder" pos="0 0 0.55" size="0.12 0.03" rgba="0.2 0.3 0.8 1" />
        <geom name="bio_ln2_handle" type="cylinder" pos="0 0.28 0.3" size="0.02 0.1" euler="90 0 0" rgba="0.5 0.5 0.5 1" />
    </body>

    

    
    <body name="biology_central_table_body" pos="4.75 4.0 0.4">
        
        <geom name="bio_central_top" type="box" pos="0 0 0.42" size="1.01 0.51 0.02" rgba="0.2 0.2 0.2 1" contype="1" conaffinity="1" />
        
        <geom name="bio_central_cab_l" type="box" pos="-0.5 0 0" size="0.45 0.45 0.4" rgba="0.9 0.9 0.9 1" />
        <geom name="bio_central_cab_r" type="box" pos="0.5 0 0" size="0.45 0.45 0.4" rgba="0.9 0.9 0.9 1" />
        
        <geom name="bio_central_mid" type="box" pos="0 0 0.2" size="0.05 0.45 0.2" rgba="0.9 0.9 0.9 1" />
        
        <geom name="bio_central_drawer_l" type="box" pos="-0.5 -0.46 0.3" size="0.4 0.01 0.08" rgba="0.8 0.8 0.8 1" />
        <geom name="bio_central_drawer_r" type="box" pos="0.5 -0.46 0.3" size="0.4 0.01 0.08" rgba="0.8 0.8 0.8 1" />
    </body>

    
    <body name="biology_large_centrifuge_body" pos="3.3 4.0 0.4">
        <geom name="bio_l_cent_case" type="box" pos="0 0 0" size="0.35 0.3 0.4" rgba="0.8 0.8 0.85 1" contype="1" conaffinity="1" />
        <geom name="bio_l_cent_lid" type="box" pos="0 0 0.41" size="0.34 0.29 0.02" rgba="0.6 0.6 0.65 1" />
        <geom name="bio_l_cent_ui" type="box" pos="0.2 -0.2 0.42" size="0.1 0.08 0.02" rgba="0.2 0.2 0.2 1" />
    </body>

    
    <body name="biology_pcr_body" pos="2.4 1.0 0.15">
        <geom name="bio_pcr_base" type="box" pos="0 0 0" size="0.25 0.2 0.1" rgba="0.8 0.8 0.8 1" contype="1" conaffinity="1" />
        <geom name="bio_pcr_lid_slope" type="box" pos="0 0 0.1" size="0.2 0.18 0.05" euler="5 0 0" rgba="0.3 0.3 0.35 1" />
        <geom name="bio_pcr_screen" type="box" pos="0 -0.15 0.08" size="0.08 0.01 0.04" euler="30 0 0" rgba="0.1 0.1 0.8 1" />
    </body>

    
    <body name="biology_gel_imaging_body" pos="3.3 1.0 0.35">
        <geom name="bio_gel_case" type="box" pos="0 0 0" size="0.3 0.25 0.35" rgba="0.3 0.3 0.3 1" contype="1" conaffinity="1" />
        <geom name="bio_gel_door" type="box" pos="0 -0.26 0" size="0.25 0.01 0.3" rgba="0.2 0.2 0.2 1" />
        <geom name="bio_gel_cam" type="box" pos="0 0 0.38" size="0.1 0.1 0.05" rgba="0.1 0.1 0.1 1" />
        <geom name="bio_gel_screen" type="box" pos="0 -0.25 0.2" size="0.08 0.02 0.06" rgba="0.5 0.8 0.5 1" />
    </body>

    
    <body name="biology_uv_spectro_body" pos="4.2 1.0 0.3">
        <geom name="bio_uv_case" type="box" pos="0 0 0" size="0.25 0.2 0.2" rgba="0.8 0.85 0.9 1" contype="1" conaffinity="1" />
        <geom name="bio_uv_sample" type="box" pos="-0.1 0.05 0.1" size="0.1 0.1 0.12" rgba="0.3 0.3 0.4 1" />
        <geom name="bio_uv_lid" type="box" pos="-0.1 0.05 0.22" size="0.11 0.11 0.01" rgba="0.3 0.3 0.4 1" />
        <geom name="bio_uv_screen" type="box" pos="0.1 -0.1 0.15" size="0.08 0.08 0.05" euler="20 0 0" rgba="0.1 0.1 0.1 1" />
    </body>

    
    <body name="biology_ultrapure_water_body" pos="5.2 2.0 0.5">
        <geom name="bio_water_case" type="box" pos="0 0 0" size="0.25 0.2 0.5" rgba="0.9 0.9 0.95 1" contype="1" conaffinity="1" />
        <geom name="bio_water_tank" type="cylinder" pos="0 0.40 -0.2" size="0.15 0.3" rgba="0.8 0.85 0.9 1" contype="1" conaffinity="1" />
        <geom name="bio_water_disp" type="capsule" pos="-0.1 -0.2 0.2" euler="45 0 0" size="0.02 0.1" rgba="0.6 0.6 0.6 1" />
        <geom name="bio_water_screen" type="box" pos="0 -0.21 0.3" size="0.1 0.01 0.06" rgba="0.1 0.1 0.8 1" />
    </body>

    
    <body name="biology_ultrasonic_disruptor_body" pos="5.2 4.0 1.09">
        <geom name="bio_sonic_gen" type="box" pos="0 0 -0.1" size="0.2 0.15 0.15" rgba="0.7 0.7 0.7 1" contype="1" conaffinity="1" />
        <geom name="bio_sonic_box" type="box" pos="0 0 0.2" size="0.15 0.15 0.25" rgba="0.8 0.8 0.8 0.5" />
        <geom name="bio_sonic_probe" type="cylinder" pos="0 0 0.25" size="0.02 0.15" rgba="0.3 0.3 0.3 1" />
    </body>

    
    <body name="biology_water_bath_body" pos="4.75 3.8 1.04">
        <geom name="bio_bath_case" type="box" pos="0 0 0" size="0.25 0.15 0.2" rgba="0.8 0.8 0.8 1" contype="1" conaffinity="1" />
        <geom name="bio_bath_water" type="box" pos="0 0 0.15" size="0.22 0.12 0.01" rgba="0.2 0.5 0.9 0.8" contype="0" conaffinity="0" />
        <geom name="bio_bath_lid" type="box" pos="0.26 0 0.18" size="0.01 0.15 0.2" euler="0 10 0" rgba="0.7 0.7 0.7 1" />
        <geom name="bio_bath_knobs" type="box" pos="-0.26 0 -0.1" size="0.01 0.1 0.05" rgba="0.2 0.2 0.2 1" />
    </body>

    
    <body name="biology_magnetic_stirrer_body" pos="4.75 4.3 0.94">
        <geom name="bio_stirrer_plate" type="box" pos="0 0 0.05" size="0.2 0.15 0.02" rgba="0.9 0.9 0.9 1" contype="1" conaffinity="1" />
        <geom name="bio_stirrer_base" type="box" pos="0 0 -0.05" size="0.2 0.15 0.05" rgba="0.3 0.3 0.4 1" contype="1" conaffinity="1" />
        <geom name="bio_stirrer_knob" type="cylinder" pos="0.18 0 -0.05" size="0.02 0.01" euler="0 90 0" rgba="0.1 0.1 0.1 1" />
    </body>

    

    
    <body name="biology_aux_side_table_body" pos="4.5 0.3 0.4">
        
        <geom name="biology_aux_side_table_top" type="box" pos="0 0 0.42" size="3.01 0.31 0.02" rgba="0.6 0.6 0.6 1" contype="1" conaffinity="1" />
        
        <geom name="bio_aux_cab_1" type="box" pos="-2.5 0 0" size="0.45 0.3 0.4" rgba="0.8 0.8 0.8 1" />
        
        <geom name="bio_aux_cab_3" type="box" pos="2.5 0 0" size="0.45 0.3 0.4" rgba="0.8 0.8 0.8 1" />
        
    </body>

    
    <body name="biology_autoclave_body" pos="1.8 1.0 0.4">
        <geom name="bio_ac_case" type="box" pos="0 0 0" size="0.3 0.3 0.4" rgba="0.85 0.85 0.85 1" contype="1" conaffinity="1" />
        <geom name="bio_ac_door" type="box" pos="0 -0.31 0" size="0.25 0.01 0.35" rgba="0.7 0.7 0.75 1" />
        <geom name="bio_ac_wheel" type="cylinder" pos="0 -0.32 0" size="0.1 0.02" euler="90 0 0" rgba="0.3 0.3 0.3 1" />
        <geom name="bio_ac_panel" type="box" pos="0.2 -0.31 0.3" size="0.08 0.01 0.05" rgba="0.2 0.2 0.2 1" />
    </body>

    
    <body name="biology_bottle_washer_body" pos="3.1 0.5 0.3">
        <geom name="bio_washer_case" type="box" pos="0 0 0" size="0.25 0.2 0.3" rgba="0.9 0.9 0.9 1" contype="1" conaffinity="1" />
        <geom name="bio_washer_win" type="box" pos="0 0.21 0.05" size="0.15 0.01 0.15" rgba="0.2 0.3 0.4 0.5" />
        <geom name="bio_washer_ui" type="box" pos="0 0.21 0.25" size="0.2 0.01 0.04" rgba="0.1 0.1 0.1 1" />
    </body>

    
    <body name="biology_waste_barrel_1_body" pos="3.75 0.5 0.3">
        <geom name="bio_waste1_body" type="cylinder" pos="0 0 0" size="0.25 0.3" rgba="0.8 0.3 0.3 1" contype="1" conaffinity="1" />
        <geom name="bio_waste1_lid" type="cylinder" pos="0 0 0.32" size="0.26 0.05" rgba="0.1 0.1 0.1 1" />
        <geom name="bio_waste1_label" type="box" pos="0 0.26 0" size="0.1 0.01 0.1" rgba="1 1 1 1" />
    </body>
    <body name="biology_waste_barrel_2_body" pos="4.45 0.5 0.3">
        <geom name="bio_waste2_body" type="cylinder" pos="0 0 0" size="0.25 0.3" rgba="0.3 0.3 0.8 1" contype="1" conaffinity="1" />
        <geom name="bio_waste2_lid" type="cylinder" pos="0 0 0.32" size="0.26 0.05" rgba="0.1 0.1 0.1 1" />
        <geom name="bio_waste2_label" type="box" pos="0 0.26 0" size="0.1 0.01 0.1" rgba="1 1 1 1" />
    </body>

    
    <body name="biology_trash_bin_1_body" pos="5.0 0.5 0.3">
        <geom name="bio_bin1_body" type="box" pos="0 0 0" size="0.2 0.2 0.3" rgba="0.8 0.2 0.2 1" contype="1" conaffinity="1" />
        <geom name="bio_bin1_lid" type="box" pos="0 0 0.31" size="0.21 0.21 0.01" euler="15 0 0" rgba="0.7 0.7 0.7 1" />
    </body>
    <body name="biology_trash_bin_2_body" pos="5.5 0.5 0.3">
        <geom name="bio_bin2_body" type="box" pos="0 0 0" size="0.2 0.2 0.3" rgba="0.2 0.2 0.8 1" contype="1" conaffinity="1" />
        <geom name="bio_bin2_lid" type="box" pos="0 0 0.31" size="0.21 0.21 0.01" euler="15 0 0" rgba="0.7 0.7 0.7 1" />
    </body>
    <body name="biology_trash_bin_3_body" pos="5.95 0.5 0.3">
        <geom name="bio_bin3_body" type="box" pos="0 0 0" size="0.2 0.2 0.3" rgba="0.2 0.2 0.2 1" contype="1" conaffinity="1" />
        <geom name="bio_bin3_lid" type="box" pos="0 0 0.31" size="0.21 0.21 0.01" euler="15 0 0" rgba="0.7 0.7 0.7 1" />
    </body>

    
    <body name="biology_consumables_cabinet_body" pos="1.5 2.0 0.9" euler="0 0 -90">
        <geom name="bio_cons_cab_frame" type="box" pos="0 0 0" size="0.5 0.25 0.9" rgba="0.9 0.9 0.9 1" contype="1" conaffinity="1" />
        <geom name="bio_cons_cab_glass" type="box" pos="0 0.26 0" size="0.45 0.01 0.85" rgba="0.5 0.8 0.9 0.3" contype="0" conaffinity="0" />
        <geom name="bio_cons_shelf_1" type="box" pos="0 0 0.3" size="0.48 0.2 0.01" rgba="0.8 0.8 0.8 1" />
        <geom name="bio_cons_shelf_2" type="box" pos="0 0 0" size="0.48 0.2 0.01" rgba="0.8 0.8 0.8 1" />
        <geom name="bio_cons_shelf_3" type="box" pos="0 0 -0.3" size="0.48 0.2 0.01" rgba="0.8 0.8 0.8 1" />
    </body>

    

    
    <body name="biology_first_aid_kit_body" pos="7.8 2.0 2.1">
      <geom name="biology_first_aid_kit" type="box" pos="0 0 0" size="0.2 0.15 0.1" rgba="0.9 0.1 0.1 1" contype="1" conaffinity="1" />
    </body>

    
    <body name="biology_eye_wash_body" pos="1.365 5.7 1.6">
      <geom name="biology_eye_wash" type="box" pos="0 0 0" size="0.1 0.15 0.25" rgba="0.3 0.5 0.9 1" contype="1" conaffinity="1" />
    </body>

    
    <body name="biology_emergency_shower_body" pos="4.75 4.0 3.2">
      <geom name="biology_emergency_shower" type="box" pos="0 0 0" size="0.25 0.25 0.15" rgba="0.3 0.7 0.9 1" contype="1" conaffinity="1" />
    </body>

    
    <body name="biology_biohazard_sign_body" pos="1.365 4.8 2.0">
      <geom name="biology_biohazard_sign" type="box" pos="0 0 0" size="0.01 0.15 0.1" rgba="0.9 0.1 0.1 1" contype="0" conaffinity="0" />
    </body>

    
    <body name="biology_temp_humidity_meter_body" pos="8.062 4.0 1.6">
      <geom name="biology_temp_humidity_meter" type="box" pos="0 0 0" size="0.075 0.05 0.025" rgba="0.3 0.3 0.3 1" contype="0" conaffinity="0" />
    </body>

    
    <body name="biology_uv_lamp_body" pos="6.9 2.0 3.2">
      <geom name="biology_uv_lamp" type="box" pos="0 0 0" size="0.6 0.05 0.025" rgba="0.9 0.9 0.9 1" contype="0" conaffinity="0" />
    </body>

    
    <camera name="overview" pos="0 9 25" xyaxes="1 0 0 0 1 0" mode="fixed" />
    <camera name="physics_view" pos="-4.25 9 10" xyaxes="0 1 0 -1 0 0" mode="fixed" />
    <camera name="chemistry_view" pos="4.25 13 12" xyaxes="0 1 0 -1 0 0" mode="fixed" />
    <camera name="biology_view" pos="4.75 4 12" xyaxes="0 1 0 -1 0 0" mode="fixed" />
  
<body name="robot1_base" quat="0 0 0 -1" childclass="ur10e_ur10e" pos="-3.0 9 0">
      <inertial mass="4.0" pos="0 0 0" diaginertia="0.0061063308908 0.0061063308908 0.01125" />
      <geom mesh="ur10e_base_0" material="ur10e_black" class="ur10e_visual" />
      <geom mesh="ur10e_base_1" material="ur10e_jointgray" class="ur10e_visual" />
      <body name="robot1_shoulder_link" pos="0 0 0.181">
        <inertial pos="0 0 0" mass="7.778" diaginertia="0.0314743 0.0314743 0.0218756" />
        <joint name="robot1_shoulder_pan_joint" class="ur10e_size4" axis="0 0 1" />
        <geom mesh="ur10e_shoulder_0" material="ur10e_urblue" class="ur10e_visual" />
        <geom mesh="ur10e_shoulder_1" material="ur10e_black" class="ur10e_visual" />
        <geom mesh="ur10e_shoulder_2" material="ur10e_jointgray" class="ur10e_visual" />
        <geom class="ur10e_collision" size="0.078 0.08" pos="0 0 -0.05" />
        <body name="robot1_upper_arm_link" pos="0 0.176 0" quat="1 0 0 0">
          <inertial pos="0 0 0.3065" mass="12.93" diaginertia="0.423074 0.423074 0.0363656" />
          <joint name="robot1_shoulder_lift_joint" class="ur10e_size4" />
          <geom mesh="ur10e_upperarm_0" material="ur10e_black" class="ur10e_visual" />
          <geom mesh="ur10e_upperarm_1" material="ur10e_jointgray" class="ur10e_visual" />
          <geom mesh="ur10e_upperarm_2" material="ur10e_urblue" class="ur10e_visual" />
          <geom mesh="ur10e_upperarm_3" material="ur10e_linkgray" class="ur10e_visual" />
          <geom class="ur10e_collision" pos="0 -0.05 0" quat="1 1 0 0" size="0.078 0.08" />
          <geom class="ur10e_collision" size="0.06 0.3" pos="0 0 0.3" />
          <body name="robot1_forearm_link" pos="0 -0.137 0.613">
            <inertial pos="0 0 0.2855" mass="3.87" diaginertia="0.11059 0.11059 0.0108844" />
            <joint name="robot1_elbow_joint" class="ur10e_size3_limited" />
            <geom mesh="ur10e_forearm_0" material="ur10e_urblue" class="ur10e_visual" />
            <geom mesh="ur10e_forearm_1" material="ur10e_black" class="ur10e_visual" />
            <geom mesh="ur10e_forearm_2" material="ur10e_jointgray" class="ur10e_visual" />
            <geom mesh="ur10e_forearm_3" material="ur10e_linkgray" class="ur10e_visual" />
            <geom class="ur10e_collision" pos="0 0.08 0" quat="1 1 0 0" size="0.058 0.065" />
            <geom class="ur10e_collision" size="0.043 0.28" pos="0 0 0.29" />
            <body name="robot1_wrist_1_link" pos="0 0 0.571" quat="1 0 1 0">
              <inertial pos="0 0.135 0" quat="0.5 0.5 -0.5 0.5" mass="1.96" diaginertia="0.0055125 0.00510825 0.00510825" />
              <joint name="robot1_wrist_1_joint" class="ur10e_size2" />
              <geom mesh="ur10e_wrist1_0" material="ur10e_black" class="ur10e_visual" />
              <geom mesh="ur10e_wrist1_1" material="ur10e_urblue" class="ur10e_visual" />
              <geom mesh="ur10e_wrist1_2" material="ur10e_jointgray" class="ur10e_visual" />
              <geom class="ur10e_collision" pos="0 0.06 0" quat="1 1 0 0" size="0.05 0.07" />
              <body name="robot1_wrist_2_link" pos="0 0.135 0">
                <inertial pos="0 0 0.12" quat="0.5 0.5 -0.5 0.5" mass="1.96" diaginertia="0.0055125 0.00510825 0.00510825" />
                <joint name="robot1_wrist_2_joint" axis="0 0 1" class="ur10e_size2" />
                <geom mesh="ur10e_wrist2_0" material="ur10e_black" class="ur10e_visual" />
                <geom mesh="ur10e_wrist2_1" material="ur10e_urblue" class="ur10e_visual" />
                <geom mesh="ur10e_wrist2_2" material="ur10e_jointgray" class="ur10e_visual" />
                <geom class="ur10e_collision" size="0.046 0.065" pos="0 0 0.05" />
                <geom class="ur10e_collision" pos="0 0.028 0.12" quat="1 1 0 0" size="0.046 0.043" />
                <body name="robot1_wrist_3_link" pos="0 0 0.12">
                  <inertial pos="0 0.092 0" quat="0 1 -1 0" mass="0.202" diaginertia="0.000204525 0.000144346 0.000144346" />
                  <joint name="robot1_wrist_3_joint" class="ur10e_size2" />
                  <geom material="ur10e_linkgray" mesh="ur10e_wrist3" class="ur10e_visual" />
                  <geom class="ur10e_eef_collision" pos="0 0.097 0" quat="1 1 0 0" size="0.046 0.02" />
                  <site name="robot1_attachment_site" pos="0 0.1 0" quat="-1 1 0 0" />
                <body name="robot1_gripper_base_mount" pos="0 0.1 0" childclass="gripper_2f85" quat="-1 1 0 0">
      <geom class="gripper_visual" mesh="gripper_base_mount" material="gripper_black" />
      <geom class="gripper_collision" mesh="gripper_base_mount" />
      <body name="robot1_gripper_base" pos="0 0 0.0038" quat="1 0 0 -1">
        <inertial mass="0.777441" pos="0 -2.70394e-05 0.0354675" quat="1 -0.00152849 0 0" diaginertia="0.000260285 0.000225381 0.000152708" />
        <geom class="gripper_visual" mesh="gripper_base" material="gripper_black" />
        <geom class="gripper_collision" mesh="gripper_base" />
        <site name="robot1_gripper_pinch" pos="0 0 0.145" type="sphere" group="5" rgba="0.9 0.9 0.9 1" size="0.005" />
        
        <body name="robot1_gripper_right_driver" pos="0 0.0306011 0.054904">
          <inertial mass="0.00899563" pos="2.96931e-12 0.0177547 0.00107314" quat="0.681301 0.732003 0 0" diaginertia="1.72352e-06 1.60906e-06 3.22006e-07" />
          <joint name="robot1_gripper_right_driver_joint" class="gripper_driver" />
          <geom class="gripper_visual" mesh="gripper_driver" material="gripper_gray" />
          <geom class="gripper_collision" mesh="gripper_driver" />
          <body name="robot1_gripper_right_coupler" pos="0 0.0315 -0.0041">
            <inertial mass="0.0140974" pos="0 0.00301209 0.0232175" quat="0.705636 -0.0455904 0.0455904 0.705636" diaginertia="4.16206e-06 3.52216e-06 8.88131e-07" />
            <joint name="robot1_gripper_right_coupler_joint" class="gripper_coupler" />
            <geom class="gripper_visual" mesh="gripper_coupler" material="gripper_black" />
            <geom class="gripper_collision" mesh="gripper_coupler" />
          </body>
        </body>
        <body name="robot1_gripper_right_spring_link" pos="0 0.0132 0.0609">
          <inertial mass="0.0221642" pos="-8.65005e-09 0.0181624 0.0212658" quat="0.663403 -0.244737 0.244737 0.663403" diaginertia="8.96853e-06 6.71733e-06 2.63931e-06" />
          <joint name="robot1_gripper_right_spring_link_joint" class="gripper_spring_link" />
          <geom class="gripper_visual" mesh="gripper_spring_link" material="gripper_black" />
          <geom class="gripper_collision" mesh="gripper_spring_link" />
          <body name="robot1_gripper_right_follower" pos="0 0.055 0.0375">
            <inertial mass="0.0125222" pos="0 -0.011046 0.0124786" quat="1 0.1664 0 0" diaginertia="2.67415e-06 2.4559e-06 6.02031e-07" />
            <joint name="robot1_gripper_right_follower_joint" class="gripper_follower" />
            <geom class="gripper_visual" mesh="gripper_follower" material="gripper_black" />
            <geom class="gripper_collision" mesh="gripper_follower" />
            <body name="robot1_gripper_right_pad" pos="0 -0.0189 0.01352">
              <geom class="gripper_pad_box1" name="robot1_gripper_right_pad1" />
              <geom class="gripper_pad_box2" name="robot1_gripper_right_pad2" />
              <inertial mass="0.0035" pos="0 -0.0025 0.0185" quat="0.707107 0 0 0.707107" diaginertia="4.73958e-07 3.64583e-07 1.23958e-07" />
              <geom class="gripper_visual" mesh="gripper_pad" />
              <body name="robot1_gripper_right_silicone_pad">
                <geom class="gripper_visual" mesh="gripper_silicone_pad" material="gripper_black" />
              </body>
            </body>
          </body>
        </body>
        
        <body name="robot1_gripper_left_driver" pos="0 -0.0306011 0.054904" quat="0 0 0 1">
          <inertial mass="0.00899563" pos="0 0.0177547 0.00107314" quat="0.681301 0.732003 0 0" diaginertia="1.72352e-06 1.60906e-06 3.22006e-07" />
          <joint name="robot1_gripper_left_driver_joint" class="gripper_driver" />
          <geom class="gripper_visual" mesh="gripper_driver" material="gripper_gray" />
          <geom class="gripper_collision" mesh="gripper_driver" />
          <body name="robot1_gripper_left_coupler" pos="0 0.0315 -0.0041">
            <inertial mass="0.0140974" pos="0 0.00301209 0.0232175" quat="0.705636 -0.0455904 0.0455904 0.705636" diaginertia="4.16206e-06 3.52216e-06 8.88131e-07" />
            <joint name="robot1_gripper_left_coupler_joint" class="gripper_coupler" />
            <geom class="gripper_visual" mesh="gripper_coupler" material="gripper_black" />
            <geom class="gripper_collision" mesh="gripper_coupler" />
          </body>
        </body>
        <body name="robot1_gripper_left_spring_link" pos="0 -0.0132 0.0609" quat="0 0 0 1">
          <inertial mass="0.0221642" pos="-8.65005e-09 0.0181624 0.0212658" quat="0.663403 -0.244737 0.244737 0.663403" diaginertia="8.96853e-06 6.71733e-06 2.63931e-06" />
          <joint name="robot1_gripper_left_spring_link_joint" class="gripper_spring_link" />
          <geom class="gripper_visual" mesh="gripper_spring_link" material="gripper_black" />
          <geom class="gripper_collision" mesh="gripper_spring_link" />
          <body name="robot1_gripper_left_follower" pos="0 0.055 0.0375">
            <inertial mass="0.0125222" pos="0 -0.011046 0.0124786" quat="1 0.1664 0 0" diaginertia="2.67415e-06 2.4559e-06 6.02031e-07" />
            <joint name="robot1_gripper_left_follower_joint" class="gripper_follower" />
            <geom class="gripper_visual" mesh="gripper_follower" material="gripper_black" />
            <geom class="gripper_collision" mesh="gripper_follower" />
            <body name="robot1_gripper_left_pad" pos="0 -0.0189 0.01352">
              <geom class="gripper_pad_box1" name="robot1_gripper_left_pad1" />
              <geom class="gripper_pad_box2" name="robot1_gripper_left_pad2" />
              <inertial mass="0.0035" pos="0 -0.0025 0.0185" quat="1 0 0 1" diaginertia="4.73958e-07 3.64583e-07 1.23958e-07" />
              <geom class="gripper_visual" mesh="gripper_pad" />
              <body name="robot1_gripper_left_silicone_pad">
                <geom class="gripper_visual" mesh="gripper_silicone_pad" material="gripper_black" />
              </body>
            </body>
          </body>
        </body>
      </body>
    </body>
  </body>
              </body>
            </body>
          </body>
        </body>
      </body>
    </body>
  
<body name="robot2_base" quat="0 0 0 -1" childclass="ur10e_ur10e" pos="-6.0 9 0">
      <inertial mass="4.0" pos="0 0 0" diaginertia="0.0061063308908 0.0061063308908 0.01125" />
      <geom mesh="ur10e_base_0" material="ur10e_black" class="ur10e_visual" />
      <geom mesh="ur10e_base_1" material="ur10e_jointgray" class="ur10e_visual" />
      <body name="robot2_shoulder_link" pos="0 0 0.181">
        <inertial pos="0 0 0" mass="7.778" diaginertia="0.0314743 0.0314743 0.0218756" />
        <joint name="robot2_shoulder_pan_joint" class="ur10e_size4" axis="0 0 1" />
        <geom mesh="ur10e_shoulder_0" material="ur10e_urblue" class="ur10e_visual" />
        <geom mesh="ur10e_shoulder_1" material="ur10e_black" class="ur10e_visual" />
        <geom mesh="ur10e_shoulder_2" material="ur10e_jointgray" class="ur10e_visual" />
        <geom class="ur10e_collision" size="0.078 0.08" pos="0 0 -0.05" />
        <body name="robot2_upper_arm_link" pos="0 0.176 0" quat="1 0 0 0">
          <inertial pos="0 0 0.3065" mass="12.93" diaginertia="0.423074 0.423074 0.0363656" />
          <joint name="robot2_shoulder_lift_joint" class="ur10e_size4" />
          <geom mesh="ur10e_upperarm_0" material="ur10e_black" class="ur10e_visual" />
          <geom mesh="ur10e_upperarm_1" material="ur10e_jointgray" class="ur10e_visual" />
          <geom mesh="ur10e_upperarm_2" material="ur10e_urblue" class="ur10e_visual" />
          <geom mesh="ur10e_upperarm_3" material="ur10e_linkgray" class="ur10e_visual" />
          <geom class="ur10e_collision" pos="0 -0.05 0" quat="1 1 0 0" size="0.078 0.08" />
          <geom class="ur10e_collision" size="0.06 0.3" pos="0 0 0.3" />
          <body name="robot2_forearm_link" pos="0 -0.137 0.613">
            <inertial pos="0 0 0.2855" mass="3.87" diaginertia="0.11059 0.11059 0.0108844" />
            <joint name="robot2_elbow_joint" class="ur10e_size3_limited" />
            <geom mesh="ur10e_forearm_0" material="ur10e_urblue" class="ur10e_visual" />
            <geom mesh="ur10e_forearm_1" material="ur10e_black" class="ur10e_visual" />
            <geom mesh="ur10e_forearm_2" material="ur10e_jointgray" class="ur10e_visual" />
            <geom mesh="ur10e_forearm_3" material="ur10e_linkgray" class="ur10e_visual" />
            <geom class="ur10e_collision" pos="0 0.08 0" quat="1 1 0 0" size="0.058 0.065" />
            <geom class="ur10e_collision" size="0.043 0.28" pos="0 0 0.29" />
            <body name="robot2_wrist_1_link" pos="0 0 0.571" quat="1 0 1 0">
              <inertial pos="0 0.135 0" quat="0.5 0.5 -0.5 0.5" mass="1.96" diaginertia="0.0055125 0.00510825 0.00510825" />
              <joint name="robot2_wrist_1_joint" class="ur10e_size2" />
              <geom mesh="ur10e_wrist1_0" material="ur10e_black" class="ur10e_visual" />
              <geom mesh="ur10e_wrist1_1" material="ur10e_urblue" class="ur10e_visual" />
              <geom mesh="ur10e_wrist1_2" material="ur10e_jointgray" class="ur10e_visual" />
              <geom class="ur10e_collision" pos="0 0.06 0" quat="1 1 0 0" size="0.05 0.07" />
              <body name="robot2_wrist_2_link" pos="0 0.135 0">
                <inertial pos="0 0 0.12" quat="0.5 0.5 -0.5 0.5" mass="1.96" diaginertia="0.0055125 0.00510825 0.00510825" />
                <joint name="robot2_wrist_2_joint" axis="0 0 1" class="ur10e_size2" />
                <geom mesh="ur10e_wrist2_0" material="ur10e_black" class="ur10e_visual" />
                <geom mesh="ur10e_wrist2_1" material="ur10e_urblue" class="ur10e_visual" />
                <geom mesh="ur10e_wrist2_2" material="ur10e_jointgray" class="ur10e_visual" />
                <geom class="ur10e_collision" size="0.046 0.065" pos="0 0 0.05" />
                <geom class="ur10e_collision" pos="0 0.028 0.12" quat="1 1 0 0" size="0.046 0.043" />
                <body name="robot2_wrist_3_link" pos="0 0 0.12">
                  <inertial pos="0 0.092 0" quat="0 1 -1 0" mass="0.202" diaginertia="0.000204525 0.000144346 0.000144346" />
                  <joint name="robot2_wrist_3_joint" class="ur10e_size2" />
                  <geom material="ur10e_linkgray" mesh="ur10e_wrist3" class="ur10e_visual" />
                  <geom class="ur10e_eef_collision" pos="0 0.097 0" quat="1 1 0 0" size="0.046 0.02" />
                  <site name="robot2_attachment_site" pos="0 0.1 0" quat="-1 1 0 0" />
                <body name="robot2_gripper_base_mount" pos="0 0.1 0" childclass="gripper_2f85" quat="-1 1 0 0">
      <geom class="gripper_visual" mesh="gripper_base_mount" material="gripper_black" />
      <geom class="gripper_collision" mesh="gripper_base_mount" />
      <body name="robot2_gripper_base" pos="0 0 0.0038" quat="1 0 0 -1">
        <inertial mass="0.777441" pos="0 -2.70394e-05 0.0354675" quat="1 -0.00152849 0 0" diaginertia="0.000260285 0.000225381 0.000152708" />
        <geom class="gripper_visual" mesh="gripper_base" material="gripper_black" />
        <geom class="gripper_collision" mesh="gripper_base" />
        <site name="robot2_gripper_pinch" pos="0 0 0.145" type="sphere" group="5" rgba="0.9 0.9 0.9 1" size="0.005" />
        
        <body name="robot2_gripper_right_driver" pos="0 0.0306011 0.054904">
          <inertial mass="0.00899563" pos="2.96931e-12 0.0177547 0.00107314" quat="0.681301 0.732003 0 0" diaginertia="1.72352e-06 1.60906e-06 3.22006e-07" />
          <joint name="robot2_gripper_right_driver_joint" class="gripper_driver" />
          <geom class="gripper_visual" mesh="gripper_driver" material="gripper_gray" />
          <geom class="gripper_collision" mesh="gripper_driver" />
          <body name="robot2_gripper_right_coupler" pos="0 0.0315 -0.0041">
            <inertial mass="0.0140974" pos="0 0.00301209 0.0232175" quat="0.705636 -0.0455904 0.0455904 0.705636" diaginertia="4.16206e-06 3.52216e-06 8.88131e-07" />
            <joint name="robot2_gripper_right_coupler_joint" class="gripper_coupler" />
            <geom class="gripper_visual" mesh="gripper_coupler" material="gripper_black" />
            <geom class="gripper_collision" mesh="gripper_coupler" />
          </body>
        </body>
        <body name="robot2_gripper_right_spring_link" pos="0 0.0132 0.0609">
          <inertial mass="0.0221642" pos="-8.65005e-09 0.0181624 0.0212658" quat="0.663403 -0.244737 0.244737 0.663403" diaginertia="8.96853e-06 6.71733e-06 2.63931e-06" />
          <joint name="robot2_gripper_right_spring_link_joint" class="gripper_spring_link" />
          <geom class="gripper_visual" mesh="gripper_spring_link" material="gripper_black" />
          <geom class="gripper_collision" mesh="gripper_spring_link" />
          <body name="robot2_gripper_right_follower" pos="0 0.055 0.0375">
            <inertial mass="0.0125222" pos="0 -0.011046 0.0124786" quat="1 0.1664 0 0" diaginertia="2.67415e-06 2.4559e-06 6.02031e-07" />
            <joint name="robot2_gripper_right_follower_joint" class="gripper_follower" />
            <geom class="gripper_visual" mesh="gripper_follower" material="gripper_black" />
            <geom class="gripper_collision" mesh="gripper_follower" />
            <body name="robot2_gripper_right_pad" pos="0 -0.0189 0.01352">
              <geom class="gripper_pad_box1" name="robot2_gripper_right_pad1" />
              <geom class="gripper_pad_box2" name="robot2_gripper_right_pad2" />
              <inertial mass="0.0035" pos="0 -0.0025 0.0185" quat="0.707107 0 0 0.707107" diaginertia="4.73958e-07 3.64583e-07 1.23958e-07" />
              <geom class="gripper_visual" mesh="gripper_pad" />
              <body name="robot2_gripper_right_silicone_pad">
                <geom class="gripper_visual" mesh="gripper_silicone_pad" material="gripper_black" />
              </body>
            </body>
          </body>
        </body>
        
        <body name="robot2_gripper_left_driver" pos="0 -0.0306011 0.054904" quat="0 0 0 1">
          <inertial mass="0.00899563" pos="0 0.0177547 0.00107314" quat="0.681301 0.732003 0 0" diaginertia="1.72352e-06 1.60906e-06 3.22006e-07" />
          <joint name="robot2_gripper_left_driver_joint" class="gripper_driver" />
          <geom class="gripper_visual" mesh="gripper_driver" material="gripper_gray" />
          <geom class="gripper_collision" mesh="gripper_driver" />
          <body name="robot2_gripper_left_coupler" pos="0 0.0315 -0.0041">
            <inertial mass="0.0140974" pos="0 0.00301209 0.0232175" quat="0.705636 -0.0455904 0.0455904 0.705636" diaginertia="4.16206e-06 3.52216e-06 8.88131e-07" />
            <joint name="robot2_gripper_left_coupler_joint" class="gripper_coupler" />
            <geom class="gripper_visual" mesh="gripper_coupler" material="gripper_black" />
            <geom class="gripper_collision" mesh="gripper_coupler" />
          </body>
        </body>
        <body name="robot2_gripper_left_spring_link" pos="0 -0.0132 0.0609" quat="0 0 0 1">
          <inertial mass="0.0221642" pos="-8.65005e-09 0.0181624 0.0212658" quat="0.663403 -0.244737 0.244737 0.663403" diaginertia="8.96853e-06 6.71733e-06 2.63931e-06" />
          <joint name="robot2_gripper_left_spring_link_joint" class="gripper_spring_link" />
          <geom class="gripper_visual" mesh="gripper_spring_link" material="gripper_black" />
          <geom class="gripper_collision" mesh="gripper_spring_link" />
          <body name="robot2_gripper_left_follower" pos="0 0.055 0.0375">
            <inertial mass="0.0125222" pos="0 -0.011046 0.0124786" quat="1 0.1664 0 0" diaginertia="2.67415e-06 2.4559e-06 6.02031e-07" />
            <joint name="robot2_gripper_left_follower_joint" class="gripper_follower" />
            <geom class="gripper_visual" mesh="gripper_follower" material="gripper_black" />
            <geom class="gripper_collision" mesh="gripper_follower" />
            <body name="robot2_gripper_left_pad" pos="0 -0.0189 0.01352">
              <geom class="gripper_pad_box1" name="robot2_gripper_left_pad1" />
              <geom class="gripper_pad_box2" name="robot2_gripper_left_pad2" />
              <inertial mass="0.0035" pos="0 -0.0025 0.0185" quat="1 0 0 1" diaginertia="4.73958e-07 3.64583e-07 1.23958e-07" />
              <geom class="gripper_visual" mesh="gripper_pad" />
              <body name="robot2_gripper_left_silicone_pad">
                <geom class="gripper_visual" mesh="gripper_silicone_pad" material="gripper_black" />
              </body>
            </body>
          </body>
        </body>
      </body>
    </body>
  </body>
              </body>
            </body>
          </body>
        </body>
      </body>
    </body>
  
  







<body name="robot3_base" quat="0 0 0 -1" childclass="ur10e_ur10e" pos="5.5 13 0">
      <inertial mass="4.0" pos="0 0 0" diaginertia="0.0061063308908 0.0061063308908 0.01125" />
      <geom mesh="ur10e_base_0" material="ur10e_black" class="ur10e_visual" />
      <geom mesh="ur10e_base_1" material="ur10e_jointgray" class="ur10e_visual" />
      <body name="robot3_shoulder_link" pos="0 0 0.181">
        <inertial pos="0 0 0" mass="7.778" diaginertia="0.0314743 0.0314743 0.0218756" />
        <joint name="robot3_shoulder_pan_joint" class="ur10e_size4" axis="0 0 1" />
        <geom mesh="ur10e_shoulder_0" material="ur10e_urblue" class="ur10e_visual" />
        <geom mesh="ur10e_shoulder_1" material="ur10e_black" class="ur10e_visual" />
        <geom mesh="ur10e_shoulder_2" material="ur10e_jointgray" class="ur10e_visual" />
        <geom class="ur10e_collision" size="0.078 0.08" pos="0 0 -0.05" />
        <body name="robot3_upper_arm_link" pos="0 0.176 0" quat="1 0 0 0">
          <inertial pos="0 0 0.3065" mass="12.93" diaginertia="0.423074 0.423074 0.0363656" />
          <joint name="robot3_shoulder_lift_joint" class="ur10e_size4" />
          <geom mesh="ur10e_upperarm_0" material="ur10e_black" class="ur10e_visual" />
          <geom mesh="ur10e_upperarm_1" material="ur10e_jointgray" class="ur10e_visual" />
          <geom mesh="ur10e_upperarm_2" material="ur10e_urblue" class="ur10e_visual" />
          <geom mesh="ur10e_upperarm_3" material="ur10e_linkgray" class="ur10e_visual" />
          <geom class="ur10e_collision" pos="0 -0.05 0" quat="1 1 0 0" size="0.078 0.08" />
          <geom class="ur10e_collision" size="0.06 0.3" pos="0 0 0.3" />
          <body name="robot3_forearm_link" pos="0 -0.137 0.613">
            <inertial pos="0 0 0.2855" mass="3.87" diaginertia="0.11059 0.11059 0.0108844" />
            <joint name="robot3_elbow_joint" class="ur10e_size3_limited" />
            <geom mesh="ur10e_forearm_0" material="ur10e_urblue" class="ur10e_visual" />
            <geom mesh="ur10e_forearm_1" material="ur10e_black" class="ur10e_visual" />
            <geom mesh="ur10e_forearm_2" material="ur10e_jointgray" class="ur10e_visual" />
            <geom mesh="ur10e_forearm_3" material="ur10e_linkgray" class="ur10e_visual" />
            <geom class="ur10e_collision" pos="0 0.08 0" quat="1 1 0 0" size="0.058 0.065" />
            <geom class="ur10e_collision" size="0.043 0.28" pos="0 0 0.29" />
            <body name="robot3_wrist_1_link" pos="0 0 0.571" quat="1 0 1 0">
              <inertial pos="0 0.135 0" quat="0.5 0.5 -0.5 0.5" mass="1.96" diaginertia="0.0055125 0.00510825 0.00510825" />
              <joint name="robot3_wrist_1_joint" class="ur10e_size2" />
              <geom mesh="ur10e_wrist1_0" material="ur10e_black" class="ur10e_visual" />
              <geom mesh="ur10e_wrist1_1" material="ur10e_urblue" class="ur10e_visual" />
              <geom mesh="ur10e_wrist1_2" material="ur10e_jointgray" class="ur10e_visual" />
              <geom class="ur10e_collision" pos="0 0.06 0" quat="1 1 0 0" size="0.05 0.07" />
              <body name="robot3_wrist_2_link" pos="0 0.135 0">
                <inertial pos="0 0 0.12" quat="0.5 0.5 -0.5 0.5" mass="1.96" diaginertia="0.0055125 0.00510825 0.00510825" />
                <joint name="robot3_wrist_2_joint" axis="0 0 1" class="ur10e_size2" />
                <geom mesh="ur10e_wrist2_0" material="ur10e_black" class="ur10e_visual" />
                <geom mesh="ur10e_wrist2_1" material="ur10e_urblue" class="ur10e_visual" />
                <geom mesh="ur10e_wrist2_2" material="ur10e_jointgray" class="ur10e_visual" />
                <geom class="ur10e_collision" size="0.046 0.065" pos="0 0 0.05" />
                <geom class="ur10e_collision" pos="0 0.028 0.12" quat="1 1 0 0" size="0.046 0.043" />
                <body name="robot3_wrist_3_link" pos="0 0 0.12">
                  <inertial pos="0 0.092 0" quat="0 1 -1 0" mass="0.202" diaginertia="0.000204525 0.000144346 0.000144346" />
                  <joint name="robot3_wrist_3_joint" class="ur10e_size2" />
                  <geom material="ur10e_linkgray" mesh="ur10e_wrist3" class="ur10e_visual" />
                  <geom class="ur10e_eef_collision" pos="0 0.097 0" quat="1 1 0 0" size="0.046 0.02" />
                  <site name="robot3_attachment_site" pos="0 0.1 0" quat="-1 1 0 0" />
                <body name="robot3_gripper_base_mount" pos="0 0.1 0" childclass="gripper_2f85" quat="-1 1 0 0">
      <geom class="gripper_visual" mesh="gripper_base_mount" material="gripper_black" />
      <geom class="gripper_collision" mesh="gripper_base_mount" />
      <body name="robot3_gripper_base" pos="0 0 0.0038" quat="1 0 0 -1">
        <inertial mass="0.777441" pos="0 -2.70394e-05 0.0354675" quat="1 -0.00152849 0 0" diaginertia="0.000260285 0.000225381 0.000152708" />
        <geom class="gripper_visual" mesh="gripper_base" material="gripper_black" />
        <geom class="gripper_collision" mesh="gripper_base" />
        <site name="robot3_gripper_pinch" pos="0 0 0.145" type="sphere" group="5" rgba="0.9 0.9 0.9 1" size="0.005" />
        
        <body name="robot3_gripper_right_driver" pos="0 0.0306011 0.054904">
          <inertial mass="0.00899563" pos="2.96931e-12 0.0177547 0.00107314" quat="0.681301 0.732003 0 0" diaginertia="1.72352e-06 1.60906e-06 3.22006e-07" />
          <joint name="robot3_gripper_right_driver_joint" class="gripper_driver" />
          <geom class="gripper_visual" mesh="gripper_driver" material="gripper_gray" />
          <geom class="gripper_collision" mesh="gripper_driver" />
          <body name="robot3_gripper_right_coupler" pos="0 0.0315 -0.0041">
            <inertial mass="0.0140974" pos="0 0.00301209 0.0232175" quat="0.705636 -0.0455904 0.0455904 0.705636" diaginertia="4.16206e-06 3.52216e-06 8.88131e-07" />
            <joint name="robot3_gripper_right_coupler_joint" class="gripper_coupler" />
            <geom class="gripper_visual" mesh="gripper_coupler" material="gripper_black" />
            <geom class="gripper_collision" mesh="gripper_coupler" />
          </body>
        </body>
        <body name="robot3_gripper_right_spring_link" pos="0 0.0132 0.0609">
          <inertial mass="0.0221642" pos="-8.65005e-09 0.0181624 0.0212658" quat="0.663403 -0.244737 0.244737 0.663403" diaginertia="8.96853e-06 6.71733e-06 2.63931e-06" />
          <joint name="robot3_gripper_right_spring_link_joint" class="gripper_spring_link" />
          <geom class="gripper_visual" mesh="gripper_spring_link" material="gripper_black" />
          <geom class="gripper_collision" mesh="gripper_spring_link" />
          <body name="robot3_gripper_right_follower" pos="0 0.055 0.0375">
            <inertial mass="0.0125222" pos="0 -0.011046 0.0124786" quat="1 0.1664 0 0" diaginertia="2.67415e-06 2.4559e-06 6.02031e-07" />
            <joint name="robot3_gripper_right_follower_joint" class="gripper_follower" />
            <geom class="gripper_visual" mesh="gripper_follower" material="gripper_black" />
            <geom class="gripper_collision" mesh="gripper_follower" />
            <body name="robot3_gripper_right_pad" pos="0 -0.0189 0.01352">
              <geom class="gripper_pad_box1" name="robot3_gripper_right_pad1" />
              <geom class="gripper_pad_box2" name="robot3_gripper_right_pad2" />
              <inertial mass="0.0035" pos="0 -0.0025 0.0185" quat="0.707107 0 0 0.707107" diaginertia="4.73958e-07 3.64583e-07 1.23958e-07" />
              <geom class="gripper_visual" mesh="gripper_pad" />
              <body name="robot3_gripper_right_silicone_pad">
                <geom class="gripper_visual" mesh="gripper_silicone_pad" material="gripper_black" />
              </body>
            </body>
          </body>
        </body>
        
        <body name="robot3_gripper_left_driver" pos="0 -0.0306011 0.054904" quat="0 0 0 1">
          <inertial mass="0.00899563" pos="0 0.0177547 0.00107314" quat="0.681301 0.732003 0 0" diaginertia="1.72352e-06 1.60906e-06 3.22006e-07" />
          <joint name="robot3_gripper_left_driver_joint" class="gripper_driver" />
          <geom class="gripper_visual" mesh="gripper_driver" material="gripper_gray" />
          <geom class="gripper_collision" mesh="gripper_driver" />
          <body name="robot3_gripper_left_coupler" pos="0 0.0315 -0.0041">
            <inertial mass="0.0140974" pos="0 0.00301209 0.0232175" quat="0.705636 -0.0455904 0.0455904 0.705636" diaginertia="4.16206e-06 3.52216e-06 8.88131e-07" />
            <joint name="robot3_gripper_left_coupler_joint" class="gripper_coupler" />
            <geom class="gripper_visual" mesh="gripper_coupler" material="gripper_black" />
            <geom class="gripper_collision" mesh="gripper_coupler" />
          </body>
        </body>
        <body name="robot3_gripper_left_spring_link" pos="0 -0.0132 0.0609" quat="0 0 0 1">
          <inertial mass="0.0221642" pos="-8.65005e-09 0.0181624 0.0212658" quat="0.663403 -0.244737 0.244737 0.663403" diaginertia="8.96853e-06 6.71733e-06 2.63931e-06" />
          <joint name="robot3_gripper_left_spring_link_joint" class="gripper_spring_link" />
          <geom class="gripper_visual" mesh="gripper_spring_link" material="gripper_black" />
          <geom class="gripper_collision" mesh="gripper_spring_link" />
          <body name="robot3_gripper_left_follower" pos="0 0.055 0.0375">
            <inertial mass="0.0125222" pos="0 -0.011046 0.0124786" quat="1 0.1664 0 0" diaginertia="2.67415e-06 2.4559e-06 6.02031e-07" />
            <joint name="robot3_gripper_left_follower_joint" class="gripper_follower" />
            <geom class="gripper_visual" mesh="gripper_follower" material="gripper_black" />
            <geom class="gripper_collision" mesh="gripper_follower" />
            <body name="robot3_gripper_left_pad" pos="0 -0.0189 0.01352">
              <geom class="gripper_pad_box1" name="robot3_gripper_left_pad1" />
              <geom class="gripper_pad_box2" name="robot3_gripper_left_pad2" />
              <inertial mass="0.0035" pos="0 -0.0025 0.0185" quat="1 0 0 1" diaginertia="4.73958e-07 3.64583e-07 1.23958e-07" />
              <geom class="gripper_visual" mesh="gripper_pad" />
              <body name="robot3_gripper_left_silicone_pad">
                <geom class="gripper_visual" mesh="gripper_silicone_pad" material="gripper_black" />
              </body>
            </body>
          </body>
        </body>
      </body>
    </body>
  </body>
              </body>
            </body>
          </body>
        </body>
      </body>
    </body>


<body name="robot4_base" quat="0 0 0 -1" childclass="ur10e_ur10e" pos="3.0 9.5 0">
      <inertial mass="4.0" pos="0 0 0" diaginertia="0.0061063308908 0.0061063308908 0.01125" />
      <geom mesh="ur10e_base_0" material="ur10e_black" class="ur10e_visual" />
      <geom mesh="ur10e_base_1" material="ur10e_jointgray" class="ur10e_visual" />
      <body name="robot4_shoulder_link" pos="0 0 0.181">
        <inertial pos="0 0 0" mass="7.778" diaginertia="0.0314743 0.0314743 0.0218756" />
        <joint name="robot4_shoulder_pan_joint" class="ur10e_size4" axis="0 0 1" />
        <geom mesh="ur10e_shoulder_0" material="ur10e_urblue" class="ur10e_visual" />
        <geom mesh="ur10e_shoulder_1" material="ur10e_black" class="ur10e_visual" />
        <geom mesh="ur10e_shoulder_2" material="ur10e_jointgray" class="ur10e_visual" />
        <geom class="ur10e_collision" size="0.078 0.08" pos="0 0 -0.05" />
        <body name="robot4_upper_arm_link" pos="0 0.176 0" quat="1 0 0 0">
          <inertial pos="0 0 0.3065" mass="12.93" diaginertia="0.423074 0.423074 0.0363656" />
          <joint name="robot4_shoulder_lift_joint" class="ur10e_size4" />
          <geom mesh="ur10e_upperarm_0" material="ur10e_black" class="ur10e_visual" />
          <geom mesh="ur10e_upperarm_1" material="ur10e_jointgray" class="ur10e_visual" />
          <geom mesh="ur10e_upperarm_2" material="ur10e_urblue" class="ur10e_visual" />
          <geom mesh="ur10e_upperarm_3" material="ur10e_linkgray" class="ur10e_visual" />
          <geom class="ur10e_collision" pos="0 -0.05 0" quat="1 1 0 0" size="0.078 0.08" />
          <geom class="ur10e_collision" size="0.06 0.3" pos="0 0 0.3" />
          <body name="robot4_forearm_link" pos="0 -0.137 0.613">
            <inertial pos="0 0 0.2855" mass="3.87" diaginertia="0.11059 0.11059 0.0108844" />
            <joint name="robot4_elbow_joint" class="ur10e_size3_limited" />
            <geom mesh="ur10e_forearm_0" material="ur10e_urblue" class="ur10e_visual" />
            <geom mesh="ur10e_forearm_1" material="ur10e_black" class="ur10e_visual" />
            <geom mesh="ur10e_forearm_2" material="ur10e_jointgray" class="ur10e_visual" />
            <geom mesh="ur10e_forearm_3" material="ur10e_linkgray" class="ur10e_visual" />
            <geom class="ur10e_collision" pos="0 0.08 0" quat="1 1 0 0" size="0.058 0.065" />
            <geom class="ur10e_collision" size="0.043 0.28" pos="0 0 0.29" />
            <body name="robot4_wrist_1_link" pos="0 0 0.571" quat="1 0 1 0">
              <inertial pos="0 0.135 0" quat="0.5 0.5 -0.5 0.5" mass="1.96" diaginertia="0.0055125 0.00510825 0.00510825" />
              <joint name="robot4_wrist_1_joint" class="ur10e_size2" />
              <geom mesh="ur10e_wrist1_0" material="ur10e_black" class="ur10e_visual" />
              <geom mesh="ur10e_wrist1_1" material="ur10e_urblue" class="ur10e_visual" />
              <geom mesh="ur10e_wrist1_2" material="ur10e_jointgray" class="ur10e_visual" />
              <geom class="ur10e_collision" pos="0 0.06 0" quat="1 1 0 0" size="0.05 0.07" />
              <body name="robot4_wrist_2_link" pos="0 0.135 0">
                <inertial pos="0 0 0.12" quat="0.5 0.5 -0.5 0.5" mass="1.96" diaginertia="0.0055125 0.00510825 0.00510825" />
                <joint name="robot4_wrist_2_joint" axis="0 0 1" class="ur10e_size2" />
                <geom mesh="ur10e_wrist2_0" material="ur10e_black" class="ur10e_visual" />
                <geom mesh="ur10e_wrist2_1" material="ur10e_urblue" class="ur10e_visual" />
                <geom mesh="ur10e_wrist2_2" material="ur10e_jointgray" class="ur10e_visual" />
                <geom class="ur10e_collision" size="0.046 0.065" pos="0 0 0.05" />
                <geom class="ur10e_collision" pos="0 0.028 0.12" quat="1 1 0 0" size="0.046 0.043" />
                <body name="robot4_wrist_3_link" pos="0 0 0.12">
                  <inertial pos="0 0.092 0" quat="0 1 -1 0" mass="0.202" diaginertia="0.000204525 0.000144346 0.000144346" />
                  <joint name="robot4_wrist_3_joint" class="ur10e_size2" />
                  <geom material="ur10e_linkgray" mesh="ur10e_wrist3" class="ur10e_visual" />
                  <geom class="ur10e_eef_collision" pos="0 0.097 0" quat="1 1 0 0" size="0.046 0.02" />
                  <site name="robot4_attachment_site" pos="0 0.1 0" quat="-1 1 0 0" />
                <body name="robot4_gripper_base_mount" pos="0 0.1 0" childclass="gripper_2f85" quat="-1 1 0 0">
      <geom class="gripper_visual" mesh="gripper_base_mount" material="gripper_black" />
      <geom class="gripper_collision" mesh="gripper_base_mount" />
      <body name="robot4_gripper_base" pos="0 0 0.0038" quat="1 0 0 -1">
        <inertial mass="0.777441" pos="0 -2.70394e-05 0.0354675" quat="1 -0.00152849 0 0" diaginertia="0.000260285 0.000225381 0.000152708" />
        <geom class="gripper_visual" mesh="gripper_base" material="gripper_black" />
        <geom class="gripper_collision" mesh="gripper_base" />
        <site name="robot4_gripper_pinch" pos="0 0 0.145" type="sphere" group="5" rgba="0.9 0.9 0.9 1" size="0.005" />
        
        <body name="robot4_gripper_right_driver" pos="0 0.0306011 0.054904">
          <inertial mass="0.00899563" pos="2.96931e-12 0.0177547 0.00107314" quat="0.681301 0.732003 0 0" diaginertia="1.72352e-06 1.60906e-06 3.22006e-07" />
          <joint name="robot4_gripper_right_driver_joint" class="gripper_driver" />
          <geom class="gripper_visual" mesh="gripper_driver" material="gripper_gray" />
          <geom class="gripper_collision" mesh="gripper_driver" />
          <body name="robot4_gripper_right_coupler" pos="0 0.0315 -0.0041">
            <inertial mass="0.0140974" pos="0 0.00301209 0.0232175" quat="0.705636 -0.0455904 0.0455904 0.705636" diaginertia="4.16206e-06 3.52216e-06 8.88131e-07" />
            <joint name="robot4_gripper_right_coupler_joint" class="gripper_coupler" />
            <geom class="gripper_visual" mesh="gripper_coupler" material="gripper_black" />
            <geom class="gripper_collision" mesh="gripper_coupler" />
          </body>
        </body>
        <body name="robot4_gripper_right_spring_link" pos="0 0.0132 0.0609">
          <inertial mass="0.0221642" pos="-8.65005e-09 0.0181624 0.0212658" quat="0.663403 -0.244737 0.244737 0.663403" diaginertia="8.96853e-06 6.71733e-06 2.63931e-06" />
          <joint name="robot4_gripper_right_spring_link_joint" class="gripper_spring_link" />
          <geom class="gripper_visual" mesh="gripper_spring_link" material="gripper_black" />
          <geom class="gripper_collision" mesh="gripper_spring_link" />
          <body name="robot4_gripper_right_follower" pos="0 0.055 0.0375">
            <inertial mass="0.0125222" pos="0 -0.011046 0.0124786" quat="1 0.1664 0 0" diaginertia="2.67415e-06 2.4559e-06 6.02031e-07" />
            <joint name="robot4_gripper_right_follower_joint" class="gripper_follower" />
            <geom class="gripper_visual" mesh="gripper_follower" material="gripper_black" />
            <geom class="gripper_collision" mesh="gripper_follower" />
            <body name="robot4_gripper_right_pad" pos="0 -0.0189 0.01352">
              <geom class="gripper_pad_box1" name="robot4_gripper_right_pad1" />
              <geom class="gripper_pad_box2" name="robot4_gripper_right_pad2" />
              <inertial mass="0.0035" pos="0 -0.0025 0.0185" quat="0.707107 0 0 0.707107" diaginertia="4.73958e-07 3.64583e-07 1.23958e-07" />
              <geom class="gripper_visual" mesh="gripper_pad" />
              <body name="robot4_gripper_right_silicone_pad">
                <geom class="gripper_visual" mesh="gripper_silicone_pad" material="gripper_black" />
              </body>
            </body>
          </body>
        </body>
        
        <body name="robot4_gripper_left_driver" pos="0 -0.0306011 0.054904" quat="0 0 0 1">
          <inertial mass="0.00899563" pos="0 0.0177547 0.00107314" quat="0.681301 0.732003 0 0" diaginertia="1.72352e-06 1.60906e-06 3.22006e-07" />
          <joint name="robot4_gripper_left_driver_joint" class="gripper_driver" />
          <geom class="gripper_visual" mesh="gripper_driver" material="gripper_gray" />
          <geom class="gripper_collision" mesh="gripper_driver" />
          <body name="robot4_gripper_left_coupler" pos="0 0.0315 -0.0041">
            <inertial mass="0.0140974" pos="0 0.00301209 0.0232175" quat="0.705636 -0.0455904 0.0455904 0.705636" diaginertia="4.16206e-06 3.52216e-06 8.88131e-07" />
            <joint name="robot4_gripper_left_coupler_joint" class="gripper_coupler" />
            <geom class="gripper_visual" mesh="gripper_coupler" material="gripper_black" />
            <geom class="gripper_collision" mesh="gripper_coupler" />
          </body>
        </body>
        <body name="robot4_gripper_left_spring_link" pos="0 -0.0132 0.0609" quat="0 0 0 1">
          <inertial mass="0.0221642" pos="-8.65005e-09 0.0181624 0.0212658" quat="0.663403 -0.244737 0.244737 0.663403" diaginertia="8.96853e-06 6.71733e-06 2.63931e-06" />
          <joint name="robot4_gripper_left_spring_link_joint" class="gripper_spring_link" />
          <geom class="gripper_visual" mesh="gripper_spring_link" material="gripper_black" />
          <geom class="gripper_collision" mesh="gripper_spring_link" />
          <body name="robot4_gripper_left_follower" pos="0 0.055 0.0375">
            <inertial mass="0.0125222" pos="0 -0.011046 0.0124786" quat="1 0.1664 0 0" diaginertia="2.67415e-06 2.4559e-06 6.02031e-07" />
            <joint name="robot4_gripper_left_follower_joint" class="gripper_follower" />
            <geom class="gripper_visual" mesh="gripper_follower" material="gripper_black" />
            <geom class="gripper_collision" mesh="gripper_follower" />
            <body name="robot4_gripper_left_pad" pos="0 -0.0189 0.01352">
              <geom class="gripper_pad_box1" name="robot4_gripper_left_pad1" />
              <geom class="gripper_pad_box2" name="robot4_gripper_left_pad2" />
              <inertial mass="0.0035" pos="0 -0.0025 0.0185" quat="1 0 0 1" diaginertia="4.73958e-07 3.64583e-07 1.23958e-07" />
              <geom class="gripper_visual" mesh="gripper_pad" />
              <body name="robot4_gripper_left_silicone_pad">
                <geom class="gripper_visual" mesh="gripper_silicone_pad" material="gripper_black" />
              </body>
            </body>
          </body>
        </body>
      </body>
    </body>
  </body>
              </body>
            </body>
          </body>
        </body>
      </body>
    </body>


<body name="robot5_base" quat="0 0 0 -1" childclass="ur10e_ur10e" pos="5.5 3.0 0">
      <inertial mass="4.0" pos="0 0 0" diaginertia="0.0061063308908 0.0061063308908 0.01125" />
      <geom mesh="ur10e_base_0" material="ur10e_black" class="ur10e_visual" />
      <geom mesh="ur10e_base_1" material="ur10e_jointgray" class="ur10e_visual" />
      <body name="robot5_shoulder_link" pos="0 0 0.181">
        <inertial pos="0 0 0" mass="7.778" diaginertia="0.0314743 0.0314743 0.0218756" />
        <joint name="robot5_shoulder_pan_joint" class="ur10e_size4" axis="0 0 1" />
        <geom mesh="ur10e_shoulder_0" material="ur10e_urblue" class="ur10e_visual" />
        <geom mesh="ur10e_shoulder_1" material="ur10e_black" class="ur10e_visual" />
        <geom mesh="ur10e_shoulder_2" material="ur10e_jointgray" class="ur10e_visual" />
        <geom class="ur10e_collision" size="0.078 0.08" pos="0 0 -0.05" />
        <body name="robot5_upper_arm_link" pos="0 0.176 0" quat="1 0 0 0">
          <inertial pos="0 0 0.3065" mass="12.93" diaginertia="0.423074 0.423074 0.0363656" />
          <joint name="robot5_shoulder_lift_joint" class="ur10e_size4" />
          <geom mesh="ur10e_upperarm_0" material="ur10e_black" class="ur10e_visual" />
          <geom mesh="ur10e_upperarm_1" material="ur10e_jointgray" class="ur10e_visual" />
          <geom mesh="ur10e_upperarm_2" material="ur10e_urblue" class="ur10e_visual" />
          <geom mesh="ur10e_upperarm_3" material="ur10e_linkgray" class="ur10e_visual" />
          <geom class="ur10e_collision" pos="0 -0.05 0" quat="1 1 0 0" size="0.078 0.08" />
          <geom class="ur10e_collision" size="0.06 0.3" pos="0 0 0.3" />
          <body name="robot5_forearm_link" pos="0 -0.137 0.613">
            <inertial pos="0 0 0.2855" mass="3.87" diaginertia="0.11059 0.11059 0.0108844" />
            <joint name="robot5_elbow_joint" class="ur10e_size3_limited" />
            <geom mesh="ur10e_forearm_0" material="ur10e_urblue" class="ur10e_visual" />
            <geom mesh="ur10e_forearm_1" material="ur10e_black" class="ur10e_visual" />
            <geom mesh="ur10e_forearm_2" material="ur10e_jointgray" class="ur10e_visual" />
            <geom mesh="ur10e_forearm_3" material="ur10e_linkgray" class="ur10e_visual" />
            <geom class="ur10e_collision" pos="0 0.08 0" quat="1 1 0 0" size="0.058 0.065" />
            <geom class="ur10e_collision" size="0.043 0.28" pos="0 0 0.29" />
            <body name="robot5_wrist_1_link" pos="0 0 0.571" quat="1 0 1 0">
              <inertial pos="0 0.135 0" quat="0.5 0.5 -0.5 0.5" mass="1.96" diaginertia="0.0055125 0.00510825 0.00510825" />
              <joint name="robot5_wrist_1_joint" class="ur10e_size2" />
              <geom mesh="ur10e_wrist1_0" material="ur10e_black" class="ur10e_visual" />
              <geom mesh="ur10e_wrist1_1" material="ur10e_urblue" class="ur10e_visual" />
              <geom mesh="ur10e_wrist1_2" material="ur10e_jointgray" class="ur10e_visual" />
              <geom class="ur10e_collision" pos="0 0.06 0" quat="1 1 0 0" size="0.05 0.07" />
              <body name="robot5_wrist_2_link" pos="0 0.135 0">
                <inertial pos="0 0 0.12" quat="0.5 0.5 -0.5 0.5" mass="1.96" diaginertia="0.0055125 0.00510825 0.00510825" />
                <joint name="robot5_wrist_2_joint" axis="0 0 1" class="ur10e_size2" />
                <geom mesh="ur10e_wrist2_0" material="ur10e_black" class="ur10e_visual" />
                <geom mesh="ur10e_wrist2_1" material="ur10e_urblue" class="ur10e_visual" />
                <geom mesh="ur10e_wrist2_2" material="ur10e_jointgray" class="ur10e_visual" />
                <geom class="ur10e_collision" size="0.046 0.065" pos="0 0 0.05" />
                <geom class="ur10e_collision" pos="0 0.028 0.12" quat="1 1 0 0" size="0.046 0.043" />
                <body name="robot5_wrist_3_link" pos="0 0 0.12">
                  <inertial pos="0 0.092 0" quat="0 1 -1 0" mass="0.202" diaginertia="0.000204525 0.000144346 0.000144346" />
                  <joint name="robot5_wrist_3_joint" class="ur10e_size2" />
                  <geom material="ur10e_linkgray" mesh="ur10e_wrist3" class="ur10e_visual" />
                  <geom class="ur10e_eef_collision" pos="0 0.097 0" quat="1 1 0 0" size="0.046 0.02" />
                  <site name="robot5_attachment_site" pos="0 0.1 0" quat="-1 1 0 0" />
                <body name="robot5_gripper_base_mount" pos="0 0.1 0" childclass="gripper_2f85" quat="-1 1 0 0">
      <geom class="gripper_visual" mesh="gripper_base_mount" material="gripper_black" />
      <geom class="gripper_collision" mesh="gripper_base_mount" />
      <body name="robot5_gripper_base" pos="0 0 0.0038" quat="1 0 0 -1">
        <inertial mass="0.777441" pos="0 -2.70394e-05 0.0354675" quat="1 -0.00152849 0 0" diaginertia="0.000260285 0.000225381 0.000152708" />
        <geom class="gripper_visual" mesh="gripper_base" material="gripper_black" />
        <geom class="gripper_collision" mesh="gripper_base" />
        <site name="robot5_gripper_pinch" pos="0 0 0.145" type="sphere" group="5" rgba="0.9 0.9 0.9 1" size="0.005" />
        
        <body name="robot5_gripper_right_driver" pos="0 0.0306011 0.054904">
          <inertial mass="0.00899563" pos="2.96931e-12 0.0177547 0.00107314" quat="0.681301 0.732003 0 0" diaginertia="1.72352e-06 1.60906e-06 3.22006e-07" />
          <joint name="robot5_gripper_right_driver_joint" class="gripper_driver" />
          <geom class="gripper_visual" mesh="gripper_driver" material="gripper_gray" />
          <geom class="gripper_collision" mesh="gripper_driver" />
          <body name="robot5_gripper_right_coupler" pos="0 0.0315 -0.0041">
            <inertial mass="0.0140974" pos="0 0.00301209 0.0232175" quat="0.705636 -0.0455904 0.0455904 0.705636" diaginertia="4.16206e-06 3.52216e-06 8.88131e-07" />
            <joint name="robot5_gripper_right_coupler_joint" class="gripper_coupler" />
            <geom class="gripper_visual" mesh="gripper_coupler" material="gripper_black" />
            <geom class="gripper_collision" mesh="gripper_coupler" />
          </body>
        </body>
        <body name="robot5_gripper_right_spring_link" pos="0 0.0132 0.0609">
          <inertial mass="0.0221642" pos="-8.65005e-09 0.0181624 0.0212658" quat="0.663403 -0.244737 0.244737 0.663403" diaginertia="8.96853e-06 6.71733e-06 2.63931e-06" />
          <joint name="robot5_gripper_right_spring_link_joint" class="gripper_spring_link" />
          <geom class="gripper_visual" mesh="gripper_spring_link" material="gripper_black" />
          <geom class="gripper_collision" mesh="gripper_spring_link" />
          <body name="robot5_gripper_right_follower" pos="0 0.055 0.0375">
            <inertial mass="0.0125222" pos="0 -0.011046 0.0124786" quat="1 0.1664 0 0" diaginertia="2.67415e-06 2.4559e-06 6.02031e-07" />
            <joint name="robot5_gripper_right_follower_joint" class="gripper_follower" />
            <geom class="gripper_visual" mesh="gripper_follower" material="gripper_black" />
            <geom class="gripper_collision" mesh="gripper_follower" />
            <body name="robot5_gripper_right_pad" pos="0 -0.0189 0.01352">
              <geom class="gripper_pad_box1" name="robot5_gripper_right_pad1" />
              <geom class="gripper_pad_box2" name="robot5_gripper_right_pad2" />
              <inertial mass="0.0035" pos="0 -0.0025 0.0185" quat="0.707107 0 0 0.707107" diaginertia="4.73958e-07 3.64583e-07 1.23958e-07" />
              <geom class="gripper_visual" mesh="gripper_pad" />
              <body name="robot5_gripper_right_silicone_pad">
                <geom class="gripper_visual" mesh="gripper_silicone_pad" material="gripper_black" />
              </body>
            </body>
          </body>
        </body>
        
        <body name="robot5_gripper_left_driver" pos="0 -0.0306011 0.054904" quat="0 0 0 1">
          <inertial mass="0.00899563" pos="0 0.0177547 0.00107314" quat="0.681301 0.732003 0 0" diaginertia="1.72352e-06 1.60906e-06 3.22006e-07" />
          <joint name="robot5_gripper_left_driver_joint" class="gripper_driver" />
          <geom class="gripper_visual" mesh="gripper_driver" material="gripper_gray" />
          <geom class="gripper_collision" mesh="gripper_driver" />
          <body name="robot5_gripper_left_coupler" pos="0 0.0315 -0.0041">
            <inertial mass="0.0140974" pos="0 0.00301209 0.0232175" quat="0.705636 -0.0455904 0.0455904 0.705636" diaginertia="4.16206e-06 3.52216e-06 8.88131e-07" />
            <joint name="robot5_gripper_left_coupler_joint" class="gripper_coupler" />
            <geom class="gripper_visual" mesh="gripper_coupler" material="gripper_black" />
            <geom class="gripper_collision" mesh="gripper_coupler" />
          </body>
        </body>
        <body name="robot5_gripper_left_spring_link" pos="0 -0.0132 0.0609" quat="0 0 0 1">
          <inertial mass="0.0221642" pos="-8.65005e-09 0.0181624 0.0212658" quat="0.663403 -0.244737 0.244737 0.663403" diaginertia="8.96853e-06 6.71733e-06 2.63931e-06" />
          <joint name="robot5_gripper_left_spring_link_joint" class="gripper_spring_link" />
          <geom class="gripper_visual" mesh="gripper_spring_link" material="gripper_black" />
          <geom class="gripper_collision" mesh="gripper_spring_link" />
          <body name="robot5_gripper_left_follower" pos="0 0.055 0.0375">
            <inertial mass="0.0125222" pos="0 -0.011046 0.0124786" quat="1 0.1664 0 0" diaginertia="2.67415e-06 2.4559e-06 6.02031e-07" />
            <joint name="robot5_gripper_left_follower_joint" class="gripper_follower" />
            <geom class="gripper_visual" mesh="gripper_follower" material="gripper_black" />
            <geom class="gripper_collision" mesh="gripper_follower" />
            <body name="robot5_gripper_left_pad" pos="0 -0.0189 0.01352">
              <geom class="gripper_pad_box1" name="robot5_gripper_left_pad1" />
              <geom class="gripper_pad_box2" name="robot5_gripper_left_pad2" />
              <inertial mass="0.0035" pos="0 -0.0025 0.0185" quat="1 0 0 1" diaginertia="4.73958e-07 3.64583e-07 1.23958e-07" />
              <geom class="gripper_visual" mesh="gripper_pad" />
              <body name="robot5_gripper_left_silicone_pad">
                <geom class="gripper_visual" mesh="gripper_silicone_pad" material="gripper_black" />
              </body>
            </body>
          </body>
        </body>
      </body>
    </body>
  </body>
              </body>
            </body>
          </body>
        </body>
      </body>
    </body>

    <body name="tidybot_base" pos="0.0 6.5 0.0" childclass="tidybot_base">
      <inertial pos="0 0 0.035" mass="60" diaginertia="0.001 0.001 0.001"/>
      <joint name="tidybot_joint_x" type="slide" axis="1 0 0"/>
      <joint name="tidybot_joint_y" type="slide" axis="0 1 0"/>
      <joint name="tidybot_joint_th" axis="0 0 1"/>
      <geom class="tidybot_visual" mesh="tidybot_bumper" material="tidybot_black"/>
      <geom class="tidybot_visual" mesh="tidybot_bottom_plate" material="tidybot_dark_gray"/>
      <geom class="tidybot_visual" mesh="tidybot_body" material="tidybot_gray"/>
      <geom class="tidybot_visual" mesh="tidybot_top_plate" material="tidybot_dark_gray"/>
      <geom class="tidybot_visual" mesh="tidybot_arm_plate" material="tidybot_gray"/>
      <geom class="tidybot_collision" mesh="tidybot_bumper"/>
      <geom class="tidybot_collision" mesh="tidybot_bottom_plate"/>
      <geom class="tidybot_collision" mesh="tidybot_body"/>
      <geom class="tidybot_collision" mesh="tidybot_top_plate"/>
      <geom class="tidybot_collision" mesh="tidybot_arm_plate"/>
    </body>
</worldbody>





<contact>
<exclude body1="robot1_gripper_base" body2="robot1_gripper_left_driver" />
    <exclude body1="robot1_gripper_base" body2="robot1_gripper_right_driver" />
    <exclude body1="robot1_gripper_base" body2="robot1_gripper_left_spring_link" />
    <exclude body1="robot1_gripper_base" body2="robot1_gripper_right_spring_link" />
    <exclude body1="robot1_gripper_right_coupler" body2="robot1_gripper_right_follower" />
    <exclude body1="robot1_gripper_left_coupler" body2="robot1_gripper_left_follower" />
  <exclude body1="robot2_gripper_base" body2="robot2_gripper_left_driver" />
    <exclude body1="robot2_gripper_base" body2="robot2_gripper_right_driver" />
    <exclude body1="robot2_gripper_base" body2="robot2_gripper_left_spring_link" />
    <exclude body1="robot2_gripper_base" body2="robot2_gripper_right_spring_link" />
    <exclude body1="robot2_gripper_right_coupler" body2="robot2_gripper_right_follower" />
    <exclude body1="robot2_gripper_left_coupler" body2="robot2_gripper_left_follower" />

    

    <exclude body1="robot3_gripper_base" body2="robot3_gripper_left_driver" />
    <exclude body1="robot3_gripper_base" body2="robot3_gripper_right_driver" />
    <exclude body1="robot3_gripper_base" body2="robot3_gripper_left_spring_link" />
    <exclude body1="robot3_gripper_base" body2="robot3_gripper_right_spring_link" />
    <exclude body1="robot3_gripper_right_coupler" body2="robot3_gripper_right_follower" />
    <exclude body1="robot3_gripper_left_coupler" body2="robot3_gripper_left_follower" />
    <exclude body1="robot4_gripper_base" body2="robot4_gripper_left_driver" />
    <exclude body1="robot4_gripper_base" body2="robot4_gripper_right_driver" />
    <exclude body1="robot4_gripper_base" body2="robot4_gripper_left_spring_link" />
    <exclude body1="robot4_gripper_base" body2="robot4_gripper_right_spring_link" />
    <exclude body1="robot4_gripper_right_coupler" body2="robot4_gripper_right_follower" />
    <exclude body1="robot4_gripper_left_coupler" body2="robot4_gripper_left_follower" />
    


    <exclude body1="robot5_gripper_base" body2="robot5_gripper_left_driver" />
    <exclude body1="robot5_gripper_base" body2="robot5_gripper_right_driver" />
    <exclude body1="robot5_gripper_base" body2="robot5_gripper_left_spring_link" />
    <exclude body1="robot5_gripper_base" body2="robot5_gripper_right_spring_link" />
    <exclude body1="robot5_gripper_right_coupler" body2="robot5_gripper_right_follower" />
    <exclude body1="robot5_gripper_left_coupler" body2="robot5_gripper_left_follower" />
    
</contact>

<tendon>
<fixed name="robot1_gripper_split">
      <joint joint="robot1_gripper_right_driver_joint" coef="0.5" />
      <joint joint="robot1_gripper_left_driver_joint" coef="0.5" />
    </fixed>
  <fixed name="robot2_gripper_split">
      <joint joint="robot2_gripper_right_driver_joint" coef="0.5" />
      <joint joint="robot2_gripper_left_driver_joint" coef="0.5" />
    </fixed>

    <fixed name="robot3_gripper_split">
      <joint joint="robot3_gripper_right_driver_joint" coef="0.5" />
      <joint joint="robot3_gripper_left_driver_joint" coef="0.5" />
    </fixed>
    <fixed name="robot4_gripper_split">
      <joint joint="robot4_gripper_right_driver_joint" coef="0.5" />
      <joint joint="robot4_gripper_left_driver_joint" coef="0.5" />
    </fixed>
    


    <fixed name="robot5_gripper_split">
      <joint joint="robot5_gripper_right_driver_joint" coef="0.5" />
      <joint joint="robot5_gripper_left_driver_joint" coef="0.5" />
    </fixed>
    
</tendon>
  

<actuator>
    <position name="tidybot_joint_x" joint="tidybot_joint_x" kp="1000000" kv="50000"/>
    <position name="tidybot_joint_y" joint="tidybot_joint_y" kp="1000000" kv="50000"/>
    <position name="tidybot_joint_th" joint="tidybot_joint_th" kp="50000" kv="1000"/>

<general class="ur10e_size4" name="robot1_shoulder_pan" joint="robot1_shoulder_pan_joint" />
    <general class="ur10e_size4" name="robot1_shoulder_lift" joint="robot1_shoulder_lift_joint" />
    <general class="ur10e_size3_limited" name="robot1_elbow" joint="robot1_elbow_joint" />
    <general class="ur10e_size2" name="robot1_wrist_1" joint="robot1_wrist_1_joint" />
    <general class="ur10e_size2" name="robot1_wrist_2" joint="robot1_wrist_2_joint" />
    <general class="ur10e_size2" name="robot1_wrist_3" joint="robot1_wrist_3_joint" />
  <general class="gripper_2f85" name="robot1_gripper_fingers_actuator" tendon="robot1_gripper_split" forcerange="-5 5" ctrlrange="0 14611" gainprm="0.3137255 0 0" biasprm="0 -100 -10" />
  <general class="ur10e_size4" name="robot2_shoulder_pan" joint="robot2_shoulder_pan_joint" />
    <general class="ur10e_size4" name="robot2_shoulder_lift" joint="robot2_shoulder_lift_joint" />
    <general class="ur10e_size3_limited" name="robot2_elbow" joint="robot2_elbow_joint" />
    <general class="ur10e_size2" name="robot2_wrist_1" joint="robot2_wrist_1_joint" />
    <general class="ur10e_size2" name="robot2_wrist_2" joint="robot2_wrist_2_joint" />
    <general class="ur10e_size2" name="robot2_wrist_3" joint="robot2_wrist_3_joint" />
  <general class="gripper_2f85" name="robot2_gripper_fingers_actuator" tendon="robot2_gripper_split" forcerange="-5 5" ctrlrange="0 14611" gainprm="0.3137255 0 0" biasprm="0 -100 -10" />

    
    

    <general class="ur10e_size4" name="robot3_shoulder_pan" joint="robot3_shoulder_pan_joint" />
    <general class="ur10e_size4" name="robot3_shoulder_lift" joint="robot3_shoulder_lift_joint" />
    <general class="ur10e_size3_limited" name="robot3_elbow" joint="robot3_elbow_joint" />
    <general class="ur10e_size2" name="robot3_wrist_1" joint="robot3_wrist_1_joint" />
    <general class="ur10e_size2" name="robot3_wrist_2" joint="robot3_wrist_2_joint" />
    <general class="ur10e_size2" name="robot3_wrist_3" joint="robot3_wrist_3_joint" />
    <general class="gripper_2f85" name="robot3_gripper_fingers_actuator" tendon="robot3_gripper_split" forcerange="-5 5" ctrlrange="0 14611" gainprm="0.3137255 0 0" biasprm="0 -100 -10" />
    <general class="ur10e_size4" name="robot4_shoulder_pan" joint="robot4_shoulder_pan_joint" />
    <general class="ur10e_size4" name="robot4_shoulder_lift" joint="robot4_shoulder_lift_joint" />
    <general class="ur10e_size3_limited" name="robot4_elbow" joint="robot4_elbow_joint" />
    <general class="ur10e_size2" name="robot4_wrist_1" joint="robot4_wrist_1_joint" />
    <general class="ur10e_size2" name="robot4_wrist_2" joint="robot4_wrist_2_joint" />
    <general class="ur10e_size2" name="robot4_wrist_3" joint="robot4_wrist_3_joint" />
    <general class="gripper_2f85" name="robot4_gripper_fingers_actuator" tendon="robot4_gripper_split" forcerange="-5 5" ctrlrange="0 14611" gainprm="0.3137255 0 0" biasprm="0 -100 -10" />
    


    <general class="ur10e_size4" name="robot5_shoulder_pan" joint="robot5_shoulder_pan_joint" />
    <general class="ur10e_size4" name="robot5_shoulder_lift" joint="robot5_shoulder_lift_joint" />
    <general class="ur10e_size3_limited" name="robot5_elbow" joint="robot5_elbow_joint" />
    <general class="ur10e_size2" name="robot5_wrist_1" joint="robot5_wrist_1_joint" />
    <general class="ur10e_size2" name="robot5_wrist_2" joint="robot5_wrist_2_joint" />
    <general class="ur10e_size2" name="robot5_wrist_3" joint="robot5_wrist_3_joint" />
    <general class="gripper_2f85" name="robot5_gripper_fingers_actuator" tendon="robot5_gripper_split" forcerange="-5 5" ctrlrange="0 14611" gainprm="0.3137255 0 0" biasprm="0 -100 -10" />
    
</actuator>

<equality>
<connect anchor="0 0 0" body1="robot1_gripper_right_follower" body2="robot1_gripper_right_coupler" solimp="0.95 0.99 0.001" solref="0.005 1" />
    <connect anchor="0 0 0" body1="robot1_gripper_left_follower" body2="robot1_gripper_left_coupler" solimp="0.95 0.99 0.001" solref="0.005 1" />
    <joint joint1="robot1_gripper_right_driver_joint" joint2="robot1_gripper_left_driver_joint" polycoef="0 1 0 0 0" solimp="0.95 0.99 0.001" solref="0.005 1" />
  <connect anchor="0 0 0" body1="robot2_gripper_right_follower" body2="robot2_gripper_right_coupler" solimp="0.95 0.99 0.001" solref="0.005 1" />
    <connect anchor="0 0 0" body1="robot2_gripper_left_follower" body2="robot2_gripper_left_coupler" solimp="0.95 0.99 0.001" solref="0.005 1" />
    <joint joint1="robot2_gripper_right_driver_joint" joint2="robot2_gripper_left_driver_joint" polycoef="0 1 0 0 0" solimp="0.95 0.99 0.001" solref="0.005 1" />

    
    

    <connect anchor="0 0 0" body1="robot3_gripper_right_follower" body2="robot3_gripper_right_coupler" solimp="0.95 0.99 0.001" solref="0.005 1" />
    <connect anchor="0 0 0" body1="robot3_gripper_left_follower" body2="robot3_gripper_left_coupler" solimp="0.95 0.99 0.001" solref="0.005 1" />
    <joint joint1="robot3_gripper_right_driver_joint" joint2="robot3_gripper_left_driver_joint" polycoef="0 1 0 0 0" solimp="0.95 0.99 0.001" solref="0.005 1" />
    <connect anchor="0 0 0" body1="robot4_gripper_right_follower" body2="robot4_gripper_right_coupler" solimp="0.95 0.99 0.001" solref="0.005 1" />
    <connect anchor="0 0 0" body1="robot4_gripper_left_follower" body2="robot4_gripper_left_coupler" solimp="0.95 0.99 0.001" solref="0.005 1" />
    <joint joint1="robot4_gripper_right_driver_joint" joint2="robot4_gripper_left_driver_joint" polycoef="0 1 0 0 0" solimp="0.95 0.99 0.001" solref="0.005 1" />
    


    <connect anchor="0 0 0" body1="robot5_gripper_right_follower" body2="robot5_gripper_right_coupler" solimp="0.95 0.99 0.001" solref="0.005 1" />
    <connect anchor="0 0 0" body1="robot5_gripper_left_follower" body2="robot5_gripper_left_coupler" solimp="0.95 0.99 0.001" solref="0.005 1" />
    <joint joint1="robot5_gripper_right_driver_joint" joint2="robot5_gripper_left_driver_joint" polycoef="0 1 0 0 0" solimp="0.95 0.99 0.001" solref="0.005 1" />
    
</equality>

</mujoco>